Workbook

Sheet Country
A1: Country | B1: Sal_2025 | C1: Cost of Living | D1: Safety | E1: Healthcare | F1: Political Stability | G1: Pollution | H1: Climate | I1: English Proficiency | J1: Openness | K1: Natural Scenery | L1: Natural Disaster
A2: Switzerland | B2: 6862.91 | C2: =VLOOKUP(A2, Sheet1!A:B, 2, FALSE) -> 74.8 | D2: =VLOOKUP(A2, Safety!A:B, 2, FALSE) -> 73.5 | E2: =VLOOKUP(A2, Health!A:B, 2, FALSE) -> 71.5 | F2: =VLOOKUP(A2, Political!A:H, 8, FALSE) -> 96.447158 | G2: =VLOOKUP(A2, Pollution!A:B, 2, FALSE) -> 23.3 | H2: 2357 | I2: =VLOOKUP(A2, English!A:C, 3, FALSE) -> 550 | J2: =VLOOKUP(A2, Openness!A:C, 2, FALSE) -> 46 | K2: =VLOOKUP(A2, Scenic!A:B, 2, FALSE) -> 4 | L2: =VLOOKUP(A2, Disaster!A:H, 3, FALSE) -> 1.05
A3: Luxembourg | B3: 5379.43 | C3: =VLOOKUP(A3, Sheet1!A:B, 2, FALSE) -> 54.8 | D3: =VLOOKUP(A3, Safety!A:B, 2, FALSE) -> 65.8 | E3: =VLOOKUP(A3, Health!A:B, 2, FALSE) -> 75.2 | F3: =VLOOKUP(A3, Political!A:H, 8, FALSE) -> 96.204395 | G3: =VLOOKUP(A3, Pollution!A:B, 2, FALSE) -> 23.3 | H3: 2218 | I3: =VLOOKUP(A3, English!A:C, 3, FALSE) -> 576 | J3: =VLOOKUP(A3, Openness!A:C, 2, FALSE) -> 38 | K3: =VLOOKUP(A3, Scenic!A:B, 2, FALSE) -> 40 | L3: =VLOOKUP(A3, Disaster!A:H, 3, FALSE) -> 0.61
A4: United States | B4: 4269.48 | C4: =VLOOKUP(A4, Sheet1!A:B, 2, FALSE) -> 54.3 | D4: =VLOOKUP(A4, Safety!A:B, 2, FALSE) -> 50.8 | E4: =VLOOKUP(A4, Health!A:B, 2, FALSE) -> 67.8 | F4: =VLOOKUP(A4, Political!A:H, 8, FALSE) -> 78.813927 | G4: =VLOOKUP(A4, Pollution!A:B, 2, FALSE) -> 36.5 | H4: 2418 | I4: 700 | J4: =VLOOKUP(A4, Openness!A:C, 2, FALSE) -> 28 | K4: =VLOOKUP(A4, Scenic!A:B, 2, FALSE) -> 51 | L4: =VLOOKUP(A4, Disaster!A:H, 3, FALSE) -> 22.56
A5: Singapore | B5: 4106.34 | C5: =VLOOKUP(A5, Sheet1!A:B, 2, FALSE) -> 73.7 | D5: =VLOOKUP(A5, Safety!A:B, 2, FALSE) -> 77.4 | E5: =VLOOKUP(A5, Health!A:B, 2, FALSE) -> 71.8 | F5: =VLOOKUP(A5, Political!A:H, 8, FALSE) -> 89.50171 | G5: =VLOOKUP(A5, Pollution!A:B, 2, FALSE) -> 32.5 | H5: 1186 | I5: =VLOOKUP(A5, English!A:C, 3, FALSE) -> 609 | J5: =VLOOKUP(A5, Openness!A:C, 2, FALSE) -> 30 | K5: =VLOOKUP(A5, Scenic!A:B, 2, FALSE) -> 33 | L5: =VLOOKUP(A5, Disaster!A:H, 3, FALSE) -> 0.8
A6: Iceland | B6: 4076.16 | C6: =VLOOKUP(A6, Sheet1!A:B, 2, FALSE) -> 65.9 | D6: =VLOOKUP(A6, Safety!A:B, 2, FALSE) -> 74.3 | E6: =VLOOKUP(A6, Health!A:B, 2, FALSE) -> 67.6 | F6: =VLOOKUP(A6, Political!A:H, 8, FALSE) -> 93.119656 | G6: =VLOOKUP(A6, Pollution!A:B, 2, FALSE) -> 16 | H6: 1012 | I6: =VLOOKUP(A6, English!A:C, 3, FALSE) -> #N/A | J6: =VLOOKUP(A6, Openness!A:C, 2, FALSE) -> #N/A | K6: =VLOOKUP(A6, Scenic!A:B, 2, FALSE) -> 8 | L6: =VLOOKUP(A6, Disaster!A:H, 3, FALSE) -> 2.01
A7: Denmark | B7: 4005.27 | C7: =VLOOKUP(A7, Sheet1!A:B, 2, FALSE) -> 48.6 | D7: =VLOOKUP(A7, Safety!A:B, 2, FALSE) -> 74 | E7: =VLOOKUP(A7, Health!A:B, 2, FALSE) -> 78.4 | F7: =VLOOKUP(A7, Political!A:H, 8, FALSE) -> 95.255514 | G7: =VLOOKUP(A7, Pollution!A:B, 2, FALSE) -> 20.8 | H7: 1961 | I7: =VLOOKUP(A7, English!A:C, 3, FALSE) -> 603 | J7: =VLOOKUP(A7, Openness!A:C, 2, FALSE) -> 45 | K7: =VLOOKUP(A7, Scenic!A:B, 2, FALSE) -> 25 | L7: =VLOOKUP(A7, Disaster!A:H, 3, FALSE) -> 0.98
A8: Australia | B8: 3945.23 | C8: =VLOOKUP(A8, Sheet1!A:B, 2, FALSE) -> 47.1 | D8: =VLOOKUP(A8, Safety!A:B, 2, FALSE) -> 52.7 | E8: =VLOOKUP(A8, Health!A:B, 2, FALSE) -> 73.4 | F8: =VLOOKUP(A8, Political!A:H, 8, FALSE) -> 92.805227 | G8: =VLOOKUP(A8, Pollution!A:B, 2, FALSE) -> 27 | H8: 3315 | I8: 700 | J8: =VLOOKUP(A8, Openness!A:C, 2, FALSE) -> 20 | K8: =VLOOKUP(A8, Scenic!A:B, 2, FALSE) -> 9 | L8: =VLOOKUP(A8, Disaster!A:H, 3, FALSE) -> 21.05
A9: Hong Kong (China) | B9: 3852.5 | C9: =VLOOKUP(A9, Sheet1!A:B, 2, FALSE) -> 65.7 | D9: =VLOOKUP(A9, Safety!A:B, 2, FALSE) -> 78.5 | E9: =VLOOKUP(A9, Health!A:B, 2, FALSE) -> 66.1 | F9: =VLOOKUP(A9, Political!A:H, 8, FALSE) -> 79.141279 | G9: =VLOOKUP(A9, Pollution!A:B, 2, FALSE) -> 67 | I9: =VLOOKUP(A9, English!A:C, 3, FALSE) -> 549 | J9: =VLOOKUP(A9, Openness!A:C, 2, FALSE) -> 27 | K9: =VLOOKUP(A9, Scenic!A:B, 2, FALSE) -> #N/A | L9: =VLOOKUP(A9, Disaster!A:H, 3, FALSE) -> #N/A
A10: Netherlands | B10: 3829.17 | C10: =VLOOKUP(A10, Sheet1!A:B, 2, FALSE) -> 47.9 | D10: =VLOOKUP(A10, Safety!A:B, 2, FALSE) -> 73.1 | E10: =VLOOKUP(A10, Health!A:B, 2, FALSE) -> 79.3 | F10: =VLOOKUP(A10, Political!A:H, 8, FALSE) -> 91.463263 | G10: =VLOOKUP(A10, Pollution!A:B, 2, FALSE) -> 21.4 | H10: 2185 | I10: =VLOOKUP(A10, English!A:C, 3, FALSE) -> 636 | J10: =VLOOKUP(A10, Openness!A:C, 2, FALSE) -> 41 | K10: =VLOOKUP(A10, Scenic!A:B, 2, FALSE) -> 21 | L10: =VLOOKUP(A10, Disaster!A:H, 3, FALSE) -> 4.11
A11: Norway | B11: 3645.41 | C11: =VLOOKUP(A11, Sheet1!A:B, 2, FALSE) -> 49.4 | D11: =VLOOKUP(A11, Safety!A:B, 2, FALSE) -> 67 | E11: =VLOOKUP(A11, Health!A:B, 2, FALSE) -> 75.6 | F11: =VLOOKUP(A11, Political!A:H, 8, FALSE) -> 94.479343 | G11: =VLOOKUP(A11, Pollution!A:B, 2, FALSE) -> 18.2 | H11: 1821 | I11: =VLOOKUP(A11, English!A:C, 3, FALSE) -> 610 | J11: =VLOOKUP(A11, Openness!A:C, 2, FALSE) -> 52 | K11: =VLOOKUP(A11, Scenic!A:B, 2, FALSE) -> 7 | L11: =VLOOKUP(A11, Disaster!A:H, 3, FALSE) -> 2.61
A12: United Kingdom | B12: 3572.87 | C12: =VLOOKUP(A12, Sheet1!A:B, 2, FALSE) -> 46.3 | D12: =VLOOKUP(A12, Safety!A:B, 2, FALSE) -> 51.7 | E12: =VLOOKUP(A12, Health!A:B, 2, FALSE) -> 72.7 | F12: =VLOOKUP(A12, Political!A:H, 8, FALSE) -> 84.892809 | G12: =VLOOKUP(A12, Pollution!A:B, 2, FALSE) -> 40.4 | H12: 2219 | I12: 700 | J12: =VLOOKUP(A12, Openness!A:C, 2, FALSE) -> 42 | K12: =VLOOKUP(A12, Scenic!A:B, 2, FALSE) -> 45 | L12: =VLOOKUP(A12, Disaster!A:H, 3, FALSE) -> 5.7
A13: United Arab Emirates | B13: 3520.47 | C13: =VLOOKUP(A13, Sheet1!A:B, 2, FALSE) -> 47.8 | D13: =VLOOKUP(A13, Safety!A:B, 2, FALSE) -> 84.5 | E13: =VLOOKUP(A13, Health!A:B, 2, FALSE) -> 70.6 | F13: =VLOOKUP(A13, Political!A:H, 8, FALSE) -> 71.24148 | G13: =VLOOKUP(A13, Pollution!A:B, 2, FALSE) -> 48.2 | H13: 1720 | I13: =VLOOKUP(A13, English!A:C, 3, FALSE) -> 489 | J13: =VLOOKUP(A13, Openness!A:C, 2, FALSE) -> 16 | K13: =VLOOKUP(A13, Scenic!A:B, 2, FALSE) -> 60 | L13: =VLOOKUP(A13, Disaster!A:H, 3, FALSE) -> 4.54
A14: New Zealand | B14: 3447.98 | C14: =VLOOKUP(A14, Sheet1!A:B, 2, FALSE) -> 41.2 | D14: =VLOOKUP(A14, Safety!A:B, 2, FALSE) -> 51.8 | E14: =VLOOKUP(A14, Health!A:B, 2, FALSE) -> 68.4 | F14: =VLOOKUP(A14, Political!A:H, 8, FALSE) -> 96.849283 | G14: =VLOOKUP(A14, Pollution!A:B, 2, FALSE) -> 26.3 | H14: 3149 | I14: 700 | J14: =VLOOKUP(A14, Openness!A:C, 2, FALSE) -> 21 | K14: =VLOOKUP(A14, Scenic!A:B, 2, FALSE) -> 2 | L14: =VLOOKUP(A14, Disaster!A:H, 3, FALSE) -> 14.34
A15: Ireland | B15: 3441.52 | C15: =VLOOKUP(A15, Sheet1!A:B, 2, FALSE) -> 50.6 | D15: =VLOOKUP(A15, Safety!A:B, 2, FALSE) -> 52.4 | E15: =VLOOKUP(A15, Health!A:B, 2, FALSE) -> 51.5 | F15: =VLOOKUP(A15, Political!A:H, 8, FALSE) -> 91.93662 | G15: =VLOOKUP(A15, Pollution!A:B, 2, FALSE) -> 34.4 | H15: 2068 | I15: 700 | J15: =VLOOKUP(A15, Openness!A:C, 2, FALSE) -> 29 | K15: =VLOOKUP(A15, Scenic!A:B, 2, FALSE) -> 11 | L15: =VLOOKUP(A15, Disaster!A:H, 3, FALSE) -> 2.55
A16: Qatar | B16: 3372.51 | C16: =VLOOKUP(A16, Sheet1!A:B, 2, FALSE) -> 41.7 | D16: =VLOOKUP(A16, Safety!A:B, 2, FALSE) -> 84.2 | E16: =VLOOKUP(A16, Health!A:B, 2, FALSE) -> 73.4 | F16: =VLOOKUP(A16, Political!A:H, 8, FALSE) -> 71.513171 | G16: =VLOOKUP(A16, Pollution!A:B, 2, FALSE) -> 60 | H16: 1851 | I16: =VLOOKUP(A16, English!A:C, 3, FALSE) -> 480 | J16: =VLOOKUP(A16, Openness!A:C, 2, FALSE) -> 22 | K16: =VLOOKUP(A16, Scenic!A:B, 2, FALSE) -> 69 | L16: =VLOOKUP(A16, Disaster!A:H, 3, FALSE) -> 0.94
A17: Israel | B17: 3301.93 | C17: =VLOOKUP(A17, Sheet1!A:B, 2, FALSE) -> 48.3 | D17: =VLOOKUP(A17, Safety!A:B, 2, FALSE) -> 68.2 | E17: =VLOOKUP(A17, Health!A:B, 2, FALSE) -> 73.2 | F17: =VLOOKUP(A17, Political!A:H, 8, FALSE) -> 67.187808 | G17: =VLOOKUP(A17, Pollution!A:B, 2, FALSE) -> 56.8 | H17: 2897 | I17: =VLOOKUP(A17, English!A:C, 3, FALSE) -> 522 | J17: =VLOOKUP(A17, Openness!A:C, 2, FALSE) -> #N/A | K17: =VLOOKUP(A17, Scenic!A:B, 2, FALSE) -> 87 | L17: =VLOOKUP(A17, Disaster!A:H, 3, FALSE) -> 3.81
A18: Germany | B18: 3287.08 | C18: =VLOOKUP(A18, Sheet1!A:B, 2, FALSE) -> 42.4 | D18: =VLOOKUP(A18, Safety!A:B, 2, FALSE) -> 60.6 | E18: =VLOOKUP(A18, Health!A:B, 2, FALSE) -> 71.9 | F18: =VLOOKUP(A18, Political!A:H, 8, FALSE) -> 87.596865 | G18: =VLOOKUP(A18, Pollution!A:B, 2, FALSE) -> 28.7 | H18: 2327 | I18: =VLOOKUP(A18, English!A:C, 3, FALSE) -> 598 | J18: =VLOOKUP(A18, Openness!A:C, 2, FALSE) -> 51 | K18: =VLOOKUP(A18, Scenic!A:B, 2, FALSE) -> 50 | L18: =VLOOKUP(A18, Disaster!A:H, 3, FALSE) -> 4.1
A19: Sweden | B19: 3072.84 | C19: =VLOOKUP(A19, Sheet1!A:B, 2, FALSE) -> 38.7 | D19: =VLOOKUP(A19, Safety!A:B, 2, FALSE) -> 52 | E19: =VLOOKUP(A19, Health!A:B, 2, FALSE) -> 68.3 | F19: =VLOOKUP(A19, Political!A:H, 8, FALSE) -> 91.941769 | G19: =VLOOKUP(A19, Pollution!A:B, 2, FALSE) -> 17.7 | H19: 1962 | I19: =VLOOKUP(A19, English!A:C, 3, FALSE) -> 608 | J19: =VLOOKUP(A19, Openness!A:C, 2, FALSE) -> 48 | K19: =VLOOKUP(A19, Scenic!A:B, 2, FALSE) -> 14 | L19: =VLOOKUP(A19, Disaster!A:H, 3, FALSE) -> 3.23
A20: Canada | B20: 3038.11 | C20: =VLOOKUP(A20, Sheet1!A:B, 2, FALSE) -> 46.1 | D20: =VLOOKUP(A20, Safety!A:B, 2, FALSE) -> 54.3 | E20: =VLOOKUP(A20, Health!A:B, 2, FALSE) -> 68.7 | F20: =VLOOKUP(A20, Political!A:H, 8, FALSE) -> 90.516576 | G20: =VLOOKUP(A20, Pollution!A:B, 2, FALSE) -> 29.7 | H20: 2015 | I20: 700 | J20: =VLOOKUP(A20, Openness!A:C, 2, FALSE) -> 39 | K20: =VLOOKUP(A20, Scenic!A:B, 2, FALSE) -> 18 | L20: =VLOOKUP(A20, Disaster!A:H, 3, FALSE) -> 18.89
A21: Finland | B21: 2987.09 | C21: =VLOOKUP(A21, Sheet1!A:B, 2, FALSE) -> 41.1 | D21: =VLOOKUP(A21, Safety!A:B, 2, FALSE) -> 73.2 | E21: =VLOOKUP(A21, Health!A:B, 2, FALSE) -> 77.5 | F21: =VLOOKUP(A21, Political!A:H, 8, FALSE) -> 93.67255 | G21: =VLOOKUP(A21, Pollution!A:B, 2, FALSE) -> 11.9 | H21: 1737 | I21: =VLOOKUP(A21, English!A:C, 3, FALSE) -> 590 | J21: =VLOOKUP(A21, Openness!A:C, 2, FALSE) -> 50 | K21: =VLOOKUP(A21, Scenic!A:B, 2, FALSE) -> 17 | L21: =VLOOKUP(A21, Disaster!A:H, 3, FALSE) -> 1.54
A22: Bahrain | B22: 2818.77 | C22: =VLOOKUP(A22, Sheet1!A:B, 2, FALSE) -> 36 | D22: =VLOOKUP(A22, Safety!A:B, 2, FALSE) -> 75.5 | E22: =VLOOKUP(A22, Health!A:B, 2, FALSE) -> #N/A | F22: =VLOOKUP(A22, Political!A:H, 8, FALSE) -> 54.024828 | G22: =VLOOKUP(A22, Pollution!A:B, 2, FALSE) -> 71.6 | I22: =VLOOKUP(A22, English!A:C, 3, FALSE) -> #N/A | J22: =VLOOKUP(A22, Openness!A:C, 2, FALSE) -> 18 | K22: =VLOOKUP(A22, Scenic!A:B, 2, FALSE) -> 84 | L22: =VLOOKUP(A22, Disaster!A:H, 3, FALSE) -> 0.94
A23: Belgium | B23: 2798.06 | C23: =VLOOKUP(A23, Sheet1!A:B, 2, FALSE) -> 40.1 | D23: =VLOOKUP(A23, Safety!A:B, 2, FALSE) -> 50.6 | E23: =VLOOKUP(A23, Health!A:B, 2, FALSE) -> 75.9 | F23: =VLOOKUP(A23, Political!A:H, 8, FALSE) -> 82.468137 | G23: =VLOOKUP(A23, Pollution!A:B, 2, FALSE) -> 49.5 | H23: 2389 | I23: =VLOOKUP(A23, English!A:C, 3, FALSE) -> 592 | J23: =VLOOKUP(A23, Openness!A:C, 2, FALSE) -> 31 | K23: =VLOOKUP(A23, Scenic!A:B, 2, FALSE) -> 47 | L23: =VLOOKUP(A23, Disaster!A:H, 3, FALSE) -> 5.1
A24: Austria | B24: 2786.82 | C24: =VLOOKUP(A24, Sheet1!A:B, 2, FALSE) -> 43.6 | D24: =VLOOKUP(A24, Safety!A:B, 2, FALSE) -> 70.5 | E24: =VLOOKUP(A24, Health!A:B, 2, FALSE) -> 77.9 | F24: =VLOOKUP(A24, Political!A:H, 8, FALSE) -> 87.594798 | G24: =VLOOKUP(A24, Pollution!A:B, 2, FALSE) -> 21.2 | H24: 2382 | I24: =VLOOKUP(A24, English!A:C, 3, FALSE) -> 600 | J24: =VLOOKUP(A24, Openness!A:C, 2, FALSE) -> 49 | K24: =VLOOKUP(A24, Scenic!A:B, 2, FALSE) -> 10 | L24: =VLOOKUP(A24, Disaster!A:H, 3, FALSE) -> 1.16
A25: France | B25: 2785.28 | C25: =VLOOKUP(A25, Sheet1!A:B, 2, FALSE) -> 41 | D25: =VLOOKUP(A25, Safety!A:B, 2, FALSE) -> 44.6 | E25: =VLOOKUP(A25, Health!A:B, 2, FALSE) -> 77.7 | F25: =VLOOKUP(A25, Political!A:H, 8, FALSE) -> 79.992172 | G25: =VLOOKUP(A25, Pollution!A:B, 2, FALSE) -> 43.7 | H25: 2710 | I25: =VLOOKUP(A25, English!A:C, 3, FALSE) -> 524 | J25: =VLOOKUP(A25, Openness!A:C, 2, FALSE) -> 34 | K25: =VLOOKUP(A25, Scenic!A:B, 2, FALSE) -> 20 | L25: =VLOOKUP(A25, Disaster!A:H, 3, FALSE) -> 7.54
A26: Kuwait | B26: 2734.78 | C26: =VLOOKUP(A26, Sheet1!A:B, 2, FALSE) -> 32.2 | D26: =VLOOKUP(A26, Safety!A:B, 2, FALSE) -> 67.2 | E26: =VLOOKUP(A26, Health!A:B, 2, FALSE) -> 58.4 | F26: =VLOOKUP(A26, Political!A:H, 8, FALSE) -> 54.095714 | G26: =VLOOKUP(A26, Pollution!A:B, 2, FALSE) -> 69.4 | H26: 2087 | I26: =VLOOKUP(A26, English!A:C, 3, FALSE) -> 456 | J26: =VLOOKUP(A26, Openness!A:C, 2, FALSE) -> 53 | K26: =VLOOKUP(A26, Scenic!A:B, 2, FALSE) -> 88 | L26: =VLOOKUP(A26, Disaster!A:H, 3, FALSE) -> 2.77
A27: South Korea | B27: 2495.16 | C27: =VLOOKUP(A27, Sheet1!A:B, 2, FALSE) -> 38.2 | D27: =VLOOKUP(A27, Safety!A:B, 2, FALSE) -> 75.1 | E27: =VLOOKUP(A27, Health!A:B, 2, FALSE) -> 82.8 | F27: =VLOOKUP(A27, Political!A:H, 8, FALSE) -> 7.5710154 | G27: =VLOOKUP(A27, Pollution!A:B, 2, FALSE) -> 61.4 | H27: 1890 | I27: =VLOOKUP(A27, English!A:C, 3, FALSE) -> 523 | J27: =VLOOKUP(A27, Openness!A:C, 2, FALSE) -> 36 | K27: =VLOOKUP(A27, Scenic!A:B, 2, FALSE) -> 70 | L27: =VLOOKUP(A27, Disaster!A:H, 3, FALSE) -> 12.38
A28: Puerto Rico | B28: 2410.53 | C28: =VLOOKUP(A28, Sheet1!A:B, 2, FALSE) -> 41.5 | D28: =VLOOKUP(A28, Safety!A:B, 2, FALSE) -> 38.5 | E28: =VLOOKUP(A28, Health!A:B, 2, FALSE) -> 58.5 | F28: =VLOOKUP(A28, Political!A:H, 8, FALSE) -> 58.691238 | G28: =VLOOKUP(A28, Pollution!A:B, 2, FALSE) -> 47.9 | I28: 700 | J28: =VLOOKUP(A28, Openness!A:C, 2, FALSE) -> #N/A | K28: =VLOOKUP(A28, Scenic!A:B, 2, FALSE) -> #N/A | L28: =VLOOKUP(A28, Disaster!A:H, 3, FALSE) -> #N/A
A29: Saudi Arabia | B29: 2386.32 | C29: =VLOOKUP(A29, Sheet1!A:B, 2, FALSE) -> 28.4 | D29: =VLOOKUP(A29, Safety!A:B, 2, FALSE) -> 76.1 | E29: =VLOOKUP(A29, Health!A:B, 2, FALSE) -> 61.8 | F29: =VLOOKUP(A29, Political!A:H, 8, FALSE) -> 54.253458 | G29: =VLOOKUP(A29, Pollution!A:B, 2, FALSE) -> 62.5 | H29: 1986 | I29: =VLOOKUP(A29, English!A:C, 3, FALSE) -> 417 | J29: =VLOOKUP(A29, Openness!A:C, 2, FALSE) -> 25 | K29: =VLOOKUP(A29, Scenic!A:B, 2, FALSE) -> 83 | L29: =VLOOKUP(A29, Disaster!A:H, 3, FALSE) -> 9.34
A30: Japan | B30: 2092.09 | C30: =VLOOKUP(A30, Sheet1!A:B, 2, FALSE) -> 31.6 | D30: =VLOOKUP(A30, Safety!A:B, 2, FALSE) -> 77.1 | E30: =VLOOKUP(A30, Health!A:B, 2, FALSE) -> 80 | F30: =VLOOKUP(A30, Political!A:H, 8, FALSE) -> 89.751469 | G30: =VLOOKUP(A30, Pollution!A:B, 2, FALSE) -> 38.5 | H30: 2190 | I30: =VLOOKUP(A30, English!A:C, 3, FALSE) -> 454 | J30: =VLOOKUP(A30, Openness!A:C, 2, FALSE) -> 35 | K30: =VLOOKUP(A30, Scenic!A:B, 2, FALSE) -> 23 | L30: =VLOOKUP(A30, Disaster!A:H, 3, FALSE) -> 20.94
A31: Oman | B31: 2068.7 | C31: =VLOOKUP(A31, Sheet1!A:B, 2, FALSE) -> 27.5 | D31: =VLOOKUP(A31, Safety!A:B, 2, FALSE) -> 81.7 | E31: =VLOOKUP(A31, Health!A:B, 2, FALSE) -> 65.1 | F31: =VLOOKUP(A31, Political!A:H, 8, FALSE) -> 57.810146 | G31: =VLOOKUP(A31, Pollution!A:B, 2, FALSE) -> 35 | H31: 1762 | I31: =VLOOKUP(A31, English!A:C, 3, FALSE) -> 421 | J31: =VLOOKUP(A31, Openness!A:C, 2, FALSE) -> 12 | K31: =VLOOKUP(A31, Scenic!A:B, 2, FALSE) -> 79 | L31: =VLOOKUP(A31, Disaster!A:H, 3, FALSE) -> 8.06
A32: Spain | B32: 2042.2 | C32: =VLOOKUP(A32, Sheet1!A:B, 2, FALSE) -> 33.6 | D32: =VLOOKUP(A32, Safety!A:B, 2, FALSE) -> 63.4 | E32: =VLOOKUP(A32, Health!A:B, 2, FALSE) -> 77.3 | F32: =VLOOKUP(A32, Political!A:H, 8, FALSE) -> 74.02275 | G32: =VLOOKUP(A32, Pollution!A:B, 2, FALSE) -> 35.4 | H32: 3001 | I32: =VLOOKUP(A32, English!A:C, 3, FALSE) -> 538 | J32: =VLOOKUP(A32, Openness!A:C, 2, FALSE) -> 11 | K32: =VLOOKUP(A32, Scenic!A:B, 2, FALSE) -> 5 | L32: =VLOOKUP(A32, Disaster!A:H, 3, FALSE) -> 9.74
A33: Cyprus | B33: 1886.76 | C33: =VLOOKUP(A33, Sheet1!A:B, 2, FALSE) -> 38.2 | D33: =VLOOKUP(A33, Safety!A:B, 2, FALSE) -> 66.9 | E33: =VLOOKUP(A33, Health!A:B, 2, FALSE) -> 57.1 | F33: =VLOOKUP(A33, Political!A:H, 8, FALSE) -> 70.662556 | G33: =VLOOKUP(A33, Pollution!A:B, 2, FALSE) -> 55.3 | H33: 2823 | I33: =VLOOKUP(A33, English!A:C, 3, FALSE) -> 558 | J33: =VLOOKUP(A33, Openness!A:C, 2, FALSE) -> 17 | K33: =VLOOKUP(A33, Scenic!A:B, 2, FALSE) -> 35 | L33: =VLOOKUP(A33, Disaster!A:H, 3, FALSE) -> 3.5
A34: Italy | B34: 1838.18 | C34: =VLOOKUP(A34, Sheet1!A:B, 2, FALSE) -> 36.3 | D34: =VLOOKUP(A34, Safety!A:B, 2, FALSE) -> 53.1 | E34: =VLOOKUP(A34, Health!A:B, 2, FALSE) -> 65.1 | F34: =VLOOKUP(A34, Political!A:H, 8, FALSE) -> 70.40189 | G34: =VLOOKUP(A34, Pollution!A:B, 2, FALSE) -> 53.8 | H34: 2758 | I34: =VLOOKUP(A34, English!A:C, 3, FALSE) -> 528 | J34: =VLOOKUP(A34, Openness!A:C, 2, FALSE) -> 33 | K34: =VLOOKUP(A34, Scenic!A:B, 2, FALSE) -> 3 | L34: =VLOOKUP(A34, Disaster!A:H, 3, FALSE) -> 11.11
A35: Czech Republic | B35: 1701.33 | C35: =VLOOKUP(A35, Sheet1!A:B, 2, FALSE) -> 31.5 | D35: =VLOOKUP(A35, Safety!A:B, 2, FALSE) -> 73.5 | E35: =VLOOKUP(A35, Health!A:B, 2, FALSE) -> 75.5 | F35: =VLOOKUP(A35, Political!A:H, 8, FALSE) -> 82.736862 | G35: =VLOOKUP(A35, Pollution!A:B, 2, FALSE) -> 34.9 | H35: 2342 | I35: =VLOOKUP(A35, English!A:C, 3, FALSE) -> 567 | J35: =VLOOKUP(A35, Openness!A:C, 2, FALSE) -> 47 | K35: =VLOOKUP(A35, Scenic!A:B, 2, FALSE) -> 53 | L35: =VLOOKUP(A35, Disaster!A:H, 3, FALSE) -> 1.09
A36: Slovenia | B36: 1701.32 | C36: =VLOOKUP(A36, Sheet1!A:B, 2, FALSE) -> 34.1 | D36: =VLOOKUP(A36, Safety!A:B, 2, FALSE) -> 76.2 | E36: =VLOOKUP(A36, Health!A:B, 2, FALSE) -> 66.1 | F36: =VLOOKUP(A36, Political!A:H, 8, FALSE) -> 79.118376 | G36: =VLOOKUP(A36, Pollution!A:B, 2, FALSE) -> 22 | H36: 2372 | I36: =VLOOKUP(A36, English!A:C, 3, FALSE) -> #N/A | J36: =VLOOKUP(A36, Openness!A:C, 2, FALSE) -> #N/A | K36: =VLOOKUP(A36, Scenic!A:B, 2, FALSE) -> 55 | L36: =VLOOKUP(A36, Disaster!A:H, 3, FALSE) -> 2.1
A37: Estonia | B37: 1688.65 | C37: =VLOOKUP(A37, Sheet1!A:B, 2, FALSE) -> 33.8 | D37: =VLOOKUP(A37, Safety!A:B, 2, FALSE) -> 76.3 | E37: =VLOOKUP(A37, Health!A:B, 2, FALSE) -> 75.5 | F37: =VLOOKUP(A37, Political!A:H, 8, FALSE) -> 86.461477 | G37: =VLOOKUP(A37, Pollution!A:B, 2, FALSE) -> 17 | H37: 1908 | I37: =VLOOKUP(A37, English!A:C, 3, FALSE) -> 578 | J37: =VLOOKUP(A37, Openness!A:C, 2, FALSE) -> #N/A | K37: =VLOOKUP(A37, Scenic!A:B, 2, FALSE) -> 62 | L37: =VLOOKUP(A37, Disaster!A:H, 3, FALSE) -> 1.77
A38: Taiwan | B38: 1644.77 | C38: =VLOOKUP(A38, Sheet1!A:B, 2, FALSE) -> 30.5 | D38: =VLOOKUP(A38, Safety!A:B, 2, FALSE) -> 82.9 | E38: =VLOOKUP(A38, Health!A:B, 2, FALSE) -> 86.5 | F38: =VLOOKUP(A38, Political!A:H, 8, FALSE) -> 85.497517 | G38: =VLOOKUP(A38, Pollution!A:B, 2, FALSE) -> 64.5 | H38: 2218 | I38: =VLOOKUP(A38, English!A:C, 3, FALSE) -> #N/A | J38: =VLOOKUP(A38, Openness!A:C, 2, FALSE) -> #N/A | K38: =VLOOKUP(A38, Scenic!A:B, 2, FALSE) -> #N/A | L38: =VLOOKUP(A38, Disaster!A:H, 3, FALSE) -> #N/A
A39: Poland | B39: 1632.99 | C39: =VLOOKUP(A39, Sheet1!A:B, 2, FALSE) -> 28.8 | D39: =VLOOKUP(A39, Safety!A:B, 2, FALSE) -> 71 | E39: =VLOOKUP(A39, Health!A:B, 2, FALSE) -> 58 | F39: =VLOOKUP(A39, Political!A:H, 8, FALSE) -> 68.085815 | G39: =VLOOKUP(A39, Pollution!A:B, 2, FALSE) -> 55.6 | H39: 2247 | I39: =VLOOKUP(A39, English!A:C, 3, FALSE) -> 588 | J39: =VLOOKUP(A39, Openness!A:C, 2, FALSE) -> 37 | K39: =VLOOKUP(A39, Scenic!A:B, 2, FALSE) -> 43 | L39: =VLOOKUP(A39, Disaster!A:H, 3, FALSE) -> 4.74
A40: Malta | B40: 1537.8 | C40: =VLOOKUP(A40, Sheet1!A:B, 2, FALSE) -> 37.1 | D40: =VLOOKUP(A40, Safety!A:B, 2, FALSE) -> 57 | E40: =VLOOKUP(A40, Health!A:B, 2, FALSE) -> 52.5 | F40: =VLOOKUP(A40, Political!A:H, 8, FALSE) -> 71.299479 | G40: =VLOOKUP(A40, Pollution!A:B, 2, FALSE) -> 75.8 | I40: =VLOOKUP(A40, English!A:C, 3, FALSE) -> #N/A | J40: =VLOOKUP(A40, Openness!A:C, 2, FALSE) -> 32 | K40: =VLOOKUP(A40, Scenic!A:B, 2, FALSE) -> #N/A | L40: =VLOOKUP(A40, Disaster!A:H, 3, FALSE) -> 1.03
...

Sheet Safety
A1: Country | B1: Safety index_2025
A2: Andorra | B2: 84.7
A3: United Arab Emirates | B3: 84.5
A4: Qatar | B4: 84.2
A5: Taiwan | B5: 82.9
A6: Oman | B6: 81.7
A7: Isle Of Man | B7: 79
A8: Hong Kong (China) | B8: 78.5
A9: Armenia | B9: 77.9
A10: Singapore | B10: 77.4
A11: Japan | B11: 77.1
A12: Monaco | B12: 76.7
A13: Estonia | B13: 76.3
... A148: Venezuela | B148: 19.3

Sheet Health
A1: Country | B1: Healthcare_2025
A2: Taiwan | B2: 86.5
A3: South Korea | B3: 82.8
A4: Japan | B4: 80
A5: Netherlands | B5: 79.3
A6: Denmark | B6: 78.4
A7: Austria | B7: 77.9
A8: France | B8: 77.7
A9: Finland | B9: 77.5
A10: Thailand | B10: 77.5
A11: Spain | B11: 77.3
A12: Ecuador | B12: 77.1
A13: Belgium | B13: 75.9
... A98: Venezuela | B98: 38.7

Sheet Political
A1: Country | B1: cc | C1: ge | D1: pv | E1: rl | F1: rq | G1: va | H1: Average | I1: Political stability_2023
A2: Afghanistan | B2: 13.679245 | C2: 1.4150944 | D2: 1.421801 | E2: 5.1886792 | F2: 9.4339619 | G2: 1.9607843 | H2: 5.5165943
A3: Albania | B3: 43.396225 | C3: 60.377357 | D3: 51.658768 | E3: 45.754719 | F3: 58.490566 | G3: 53.92157 | H3: 52.266534
A4: Algeria | B4: 30.188679 | C4: 27.35849 | D4: 23.22275 | E4: 26.415094 | F4: 16.037735 | G4: 22.058823 | H4: 24.213595
A5: American Samoa | B5: 87.735847 | C5: 73.113205 | D5: 91.94313 | E5: 85.377357 | F5: 68.396225 | H5: 81.313153
A6: Andorra | B6: 87.735847 | C6: 91.037735 | D6: 98.578201 | E6: 91.509438 | F6: 89.622643 | G6: 78.92157 | H6: 89.567572
A7: Angola | B7: 29.245283 | C7: 14.622642 | D7: 32.227489 | E7: 14.622642 | F7: 22.64151 | G7: 27.941177 | H7: 23.550124
A8: Anguilla | B8: 87.735847 | C8: 87.264153 | D8: 91.94313 | E8: 75 | F8: 79.245285 | H8: 84.237683
A9: Antigua and Barbuda | B9: 62.264153 | C9: 63.679245 | D9: 80.568718 | E9: 59.905659 | F9: 70.28302 | G9: 70.098038 | H9: 67.799805
A10: Argentina | B10: 41.981133 | C10: 36.320755 | D10: 41.706161 | E10: 37.735847 | F10: 35.377357 | G10: 63.235294 | H10: 42.726091
A11: Armenia | B11: 57.07547 | C11: 43.867924 | D11: 17.061611 | E11: 49.056602 | F11: 52.830189 | G11: 50.490196 | H11: 45.063665
A12: Aruba | B12: 75.471695 | C12: 78.301888 | D12: 97.630333 | E12: 87.264153 | F12: 80.188683 | G12: 80.392159 | H12: 83.208151
A13: Australia | B13: 95.754715 | C13: 93.867928 | D13: 79.62085 | E13: 91.981133 | F13: 99.528305 | G13: 96.07843 | H13: 92.805227
A14: Austria | B14: 83.490562 | C14: 89.622643 | D14: 71.56398 | E14: 97.169815 | F14: 90.094337 | G14: 93.627449 | H14: 87.594798
A15: Azerbaijan | B15: 12.264151 | C15: 50.471699 | D15: 18.00948 | E15: 29.245283 | F15: 49.056602 | G15: 9.3137255 | H15: 28.060157
A16: Bahamas, The | B16: 88.20755 | C16: 61.792454 | D16: 84.834122 | E16: 55.660378 | F16: 51.886791 | G16: 74.019608 | H16: 69.40015
A17: Bahrain | B17: 59.433964 | C17: 74.528305 | D17: 29.383886 | E17: 65.56604 | F17: 83.962265 | G17: 11.274509 | H17: 54.024828
A18: Bangladesh | B18: 14.622642 | C18: 26.886793 | D18: 15.639811 | E18: 33.490566 | F18: 18.867924 | G18: 27.450981 | H18: 22.826453
A19: Barbados | B19: 89.622643 | C19: 64.15094 | D19: 93.83886 | E19: 62.264153 | F19: 67.452827 | G19: 87.254906 | H19: 77.430721
A20: Belarus | B20: 26.886793 | C20: 15.094339 | D20: 18.483412 | E20: 11.320755 | F20: 7.5471697 | G20: 3.9215686 | H20: 13.875673
... A23: Benin | B23: 52.830189 | C23: 42.452831 | D23: 31.753555 | E23: 33.018867 | F23: 40.566036 | G23: 40.196079 | H23: 40.13626
A24: Bermuda | B24: 87.735847 | C24: 87.264153 | D24: 86.729858 | E24: 75 | F24: 79.245285 | H24: 83.195029
A25: Bhutan | B25: 91.037735 | C25: 69.339622 | D25: 83.412323 | E25: 72.64151 | F25: 36.792454 | G25: 54.901962 | H25: 68.020934
A26: Bolivia | B26: 21.698112 | C26: 29.245283 | D26: 35.071091 | E26: 11.792453 | F26: 11.792453 | G26: 39.215687 | H26: 24.802513
A27: Bosnia and Herzegovina | B27: 30.660378 | C27: 15.566038 | D27: 31.279621 | E27: 39.622643 | F27: 46.698112 | G27: 38.235294 | H27: 33.677014
A28: Botswana | B28: 73.584908 | C28: 66.981133 | D28: 87.203789 | E28: 61.320755 | F28: 66.981133 | G28: 62.745098 | H28: 69.802802
A29: Brazil | B29: 34.433964 | C29: 32.07547 | D29: 28.43602 | E29: 41.981133 | F29: 40.094341 | G29: 59.803921 | H29: 39.470808
A30: Brunei Darussalam | B30: 88.679245 | C30: 90.094337 | D30: 96.682465 | E30: 79.245285 | F30: 80.660378 | G30: 28.921568 | H30: 77.380546
A31: Bulgaria | B31: 50 | C31: 53.301888 | D31: 55.450237 | E31: 53.773586 | F31: 65.56604 | G31: 60.294117 | H31: 56.397645
A32: Burkina Faso | B32: 49.528301 | C32: 21.226416 | D32: 5.6872039 | E32: 24.528301 | F32: 34.905659 | G32: 25.490196 | H32: 26.894346
A33: Burundi | B33: 3.3018868 | C33: 11.320755 | D33: 12.796208 | E33: 10.849056 | F33: 15.566038 | G33: 11.764706 | H33: 10.933108
A34: Cambodia | B34: 9.4339619 | C34: 38.207546 | D34: 47.867298 | E34: 23.584906 | F34: 25.471699 | G34: 12.745098 | H34: 26.218418
A35: Cameroon | B35: 13.207547 | C35: 17.452829 | D35: 11.374408 | E35: 16.509434 | F35: 19.339622 | G35: 19.607843 | H35: 16.248614
A36: Canada | B36: 94.811317 | C36: 91.981133 | D36: 76.303314 | E36: 90.094337 | F36: 94.811317 | G36: 95.098038 | H36: 90.516576
... A77: Grenada | B77: 68.396225 | C77: 50.943398 | D77: 86.25592 | E77: 69.339622 | F77: 61.792454 | G77: 71.07843 | H77: 67.967675
A78: Guam | B78: 87.735847 | C78: 73.113205 | D78: 78.199051 | E78: 81.603775 | F78: 68.396225 | H78: 77.809621
A79: Guatemala | B79: 14.150944 | C79: 18.396227 | D79: 36.966824 | E79: 15.566038 | F79: 41.509434 | G79: 33.333332 | H79: 26.6538
A80: Guinea | B80: 20.283018 | C80: 16.981133 | D80: 16.113745 | E80: 14.150944 | F80: 13.207547 | G80: 17.647058 | H80: 16.397241
A81: Guinea-Bissau | B81: 12.735849 | C81: 8.0188675 | D81: 34.123222 | E81: 7.0754719 | F81: 9.9056606 | G81: 36.274509 | H81: 18.022264
A82: Guyana | B82: 40.566036 | C82: 39.622643 | D82: 43.601894 | E82: 40.566036 | F82: 31.603773 | G82: 52.941177 | H82: 41.483593
...

Sheet Pollution
A1: Country | B1: Pollution_2025 | C1: Exp Pollution Index
A2: Cameroon | B2: 93.7 | C2: 169.8
A3: Myanmar | B3: 89.8 | C3: 162.2
A4: Lebanon | B4: 89.4 | C4: 159.8
A5: Nigeria | B5: 88.2 | C5: 157.5
A6: Mongolia | B6: 87.8 | C6: 160.4
A7: Ghana | B7: 87 | C7: 155.8
A8: Bangladesh | B8: 85.6 | C8: 153
A9: Afghanistan | B9: 84.4 | C9: 150.5
A10: Vietnam | B10: 84.2 | C10: 150.4
A11: Nepal | B11: 84.2 | C11: 149.6
A12: Egypt | B12: 82.7 | C12: 146.8
A13: Peru | B13: 82.5 | C13: 146.7
... A114: Finland | B114: 11.9 | C114: 19.9

Sheet Climate
A1: Country | B1: Climate_2025 | C1: Climate_2026 | D1: This is Christophs data from Georank. its Comfortable outdoor hours / year
A2: Venezuela | B2: 99.9
A3: Kenya | B3: 99.8
A4: Costa Rica | B4: 99.5
A5: Ecuador | B5: 98.7
A6: Colombia | B6: 98.4
A7: Argentina | B7: 98.3
A8: Uruguay | B8: 98
A9: Peru | B9: 97.7
A10: Malta | B10: 97.4
A11: Brazil | B11: 97.4
A12: Portugal | B12: 97.3
A13: New Zealand | B13: 95.5
... A89: Kuwait | B89: 20.2

Sheet English
A1: Country/Region | B1: Proficiency Band | C1: Score | D1: Source: https://www.ef.com/wwen/epi/
A2: Netherlands | B2: Very high proficiency | C2: 636 | D2: =IF(B2="Very high proficiency",100, IF(B2="High proficiency",80, IF(B2="Moderate proficiency",60, IF(B2="Low proficiency",40, IF(B2="Very low proficiency",20))))) -> 100 | F2: English_2024 | J2: Very high proficiency | K2: 100
A3: Norway | B3: Very high proficiency | C3: 610 | D3: =IF(B3="Very high proficiency",100, IF(B3="High proficiency",80, IF(B3="Moderate proficiency",60, IF(B3="Low proficiency",40, IF(B3="Very low proficiency",20))))) -> 100 | J3: High proficiency | K3: 80
A4: Singapore | B4: Very high proficiency | C4: 609 | D4: =IF(B4="Very high proficiency",100, IF(B4="High proficiency",80, IF(B4="Moderate proficiency",60, IF(B4="Low proficiency",40, IF(B4="Very low proficiency",20))))) -> 100 | J4: Moderate proficiency | K4: 60
A5: Sweden | B5: Very high proficiency | C5: 608 | D5: =IF(B5="Very high proficiency",100, IF(B5="High proficiency",80, IF(B5="Moderate proficiency",60, IF(B5="Low proficiency",40, IF(B5="Very low proficiency",20))))) -> 100 | J5: Low proficiency | K5: 40
A6: Croatia | B6: Very high proficiency | C6: 607 | D6: =IF(B6="Very high proficiency",100, IF(B6="High proficiency",80, IF(B6="Moderate proficiency",60, IF(B6="Low proficiency",40, IF(B6="Very low proficiency",20))))) -> 100 | J6: Very low proficiency | K6: 20
A7: Portugal | B7: Very high proficiency | C7: 605 | D7: =IF(B7="Very high proficiency",100, IF(B7="High proficiency",80, IF(B7="Moderate proficiency",60, IF(B7="Low proficiency",40, IF(B7="Very low proficiency",20))))) -> 100
A8: Denmark | B8: Very high proficiency | C8: 603 | D8: =IF(B8="Very high proficiency",100, IF(B8="High proficiency",80, IF(B8="Moderate proficiency",60, IF(B8="Low proficiency",40, IF(B8="Very low proficiency",20))))) -> 100
A9: Greece | B9: Very high proficiency | C9: 602 | D9: =IF(B9="Very high proficiency",100, IF(B9="High proficiency",80, IF(B9="Moderate proficiency",60, IF(B9="Low proficiency",40, IF(B9="Very low proficiency",20))))) -> 100
A10: Austria | B10: Very high proficiency | C10: 600 | D10: =IF(B10="Very high proficiency",100, IF(B10="High proficiency",80, IF(B10="Moderate proficiency",60, IF(B10="Low proficiency",40, IF(B10="Very low proficiency",20))))) -> 100
A11: Germany | B11: High Proficiency | C11: 598 | D11: =IF(B11="Very high proficiency",100, IF(B11="High proficiency",80, IF(B11="Moderate proficiency",60, IF(B11="Low proficiency",40, IF(B11="Very low proficiency",20))))) -> 80
A12: South Africa | B12: High Proficiency | C12: 594 | D12: =IF(B12="Very high proficiency",100, IF(B12="High proficiency",80, IF(B12="Moderate proficiency",60, IF(B12="Low proficiency",40, IF(B12="Very low proficiency",20))))) -> 80
A13: Romania | B13: High proficiency | C13: 593 | D13: =IF(B13="Very high proficiency",100, IF(B13="High proficiency",80, IF(B13="Moderate proficiency",60, IF(B13="Low proficiency",40, IF(B13="Very low proficiency",20))))) -> 80
A14: Belgium | B14: High Proficiency | C14: 592 | D14: =IF(B14="Very high proficiency",100, IF(B14="High proficiency",80, IF(B14="Moderate proficiency",60, IF(B14="Low proficiency",40, IF(B14="Very low proficiency",20))))) -> 80
A15: Finland | B15: High proficiency | C15: 590 | D15: =IF(B15="Very high proficiency",100, IF(B15="High proficiency",80, IF(B15="Moderate proficiency",60, IF(B15="Low proficiency",40, IF(B15="Very low proficiency",20))))) -> 80
A16: Poland | B16: High proficiency | C16: 588 | D16: =IF(B16="Very high proficiency",100, IF(B16="High proficiency",80, IF(B16="Moderate proficiency",60, IF(B16="Low proficiency",40, IF(B16="Very low proficiency",20))))) -> 80
A17: Bulgaria | B17: High proficiency | C17: 586 | D17: =IF(B17="Very high proficiency",100, IF(B17="High proficiency",80, IF(B17="Moderate proficiency",60, IF(B17="Low proficiency",40, IF(B17="Very low proficiency",20))))) -> 80
A18: Hungary | B18: High proficiency | C18: 585 | D18: =IF(B18="Very high proficiency",100, IF(B18="High proficiency",80, IF(B18="Moderate proficiency",60, IF(B18="Low proficiency",40, IF(B18="Very low proficiency",20))))) -> 80
... A117: Yemen | B117: Very low proficiency | C117: 394 | D117: =IF(B117="Very high proficiency",100, IF(B117="High proficiency",80, IF(B117="Moderate proficiency",60, IF(B117="Low proficiency",40, IF(B117="Very low proficiency",20))))) -> 20

Sheet Openness
A1: Ease of settling in | B1: Openness_2024 | C1: Source https://www.internations.org/expat-insider/2024/ease-of-settling-in-index-40452#methodology
A2: Costa Rica | B2: 1 | C2: This is made up of 3 sub indexes: welcome & culture, Local friendliness, and finding friends
A3: Mexico | B3: 2
A4: Philippines | B4: 3
A5: Indonesia | B5: 4
A6: Brazil | B6: 5
A7: Thailand | B7: 6
A8: Panama | B8: 7
A9: Colombia | B9: 8
A10: Kenya | B10: 9
A11: Greece | B11: 10
A12: Spain | B12: 11
A13: Oman | B13: 12
A14: Vietnam | B14: 13
... A54: Kuwait | B54: 53

Sheet Scenic
A1: Country | B1: Rank | C1: source https://www.usnews.com/news/best-countries/rankings/scenic?utm_source=chatgpt.com
A2: Greece | B2: 1 | C2: 2024 data
A3: New Zealand | B3: 2
A4: Italy | B4: 3
A5: Switzerland | B5: 4
A6: Spain | B6: 5
A7: Thailand | B7: 6
A8: Norway | B8: 7
A9: Iceland | B9: 8
A10: Australia | B10: 9
A11: Austria | B11: 10
A12: Ireland | B12: 11
A13: Brazil | B13: 12
A14: Portugal | B14: 13
... A90: Iran | B90: 89

Sheet Disaster
A1: WRI.Country | B1: ISO3.Code | C1: W | D1: E | E1: V | F1: S | G1: C | H1: A | I1: Source | J1: https://reliefweb.int/report/world/worldriskreport-2024-focus-multiple-crises?utm_source=chatgpt.com
A2: Philippines | B2: PHL | C2: 46.91 | D2: 39.99 | E2: 55.03 | F2: 51.16 | G2: 58.07 | H2: 56.1 | J2: Disaster_2024
A3: Indonesia | B3: IDN | C3: 41.13 | D3: 39.89 | E3: 42.4 | F3: 32.37 | G3: 51.01 | H3: 46.17
A4: India | B4: IND | C4: 40.96 | D4: 35.99 | E4: 46.62 | F4: 37.15 | G4: 54.01 | H4: 50.49
A5: Colombia | B5: COL | C5: 37.81 | D5: 31.54 | E5: 45.33 | F5: 39.3 | G5: 49.28 | H5: 48.1
A6: Mexico | B6: MEX | C6: 35.93 | D6: 50.08 | E6: 25.78 | F6: 30.03 | G6: 11.97 | H6: 47.68
A7: Myanmar | B7: MMR | C7: 35.85 | D7: 22.43 | E7: 57.31 | F7: 51.43 | G7: 58.75 | H7: 62.29
A8: Mozambique | B8: MOZ | C8: 34.44 | D8: 18.1 | E8: 65.53 | F8: 65.79 | G8: 63.13 | H8: 67.75
A9: Russia | B9: RUS | C9: 28.12 | D9: 28.35 | E9: 27.89 | F9: 15.31 | G9: 40.03 | H9: 35.38
A10: Bangladesh | B10: BGD | C10: 27.73 | D10: 16.57 | E10: 46.39 | F10: 35.5 | G10: 57.92 | H10: 48.54
A11: Pakistan | B11: PAK | C11: 27.02 | D11: 13.11 | E11: 55.69 | F11: 42.64 | G11: 63.1 | H11: 64.18
A12: Peru | B12: PER | C12: 27.01 | D12: 16.65 | E12: 43.82 | F12: 36.32 | G12: 46.06 | H12: 50.3
A13: Papua New Guinea | B13: PNG | C13: 26.35 | D13: 18.84 | E13: 36.84 | F13: 57.46 | G13: 13.59 | H13: 64.04
A14: Madagascar | B14: MDG | C14: 24.8 | D14: 18.38 | E14: 33.47 | F14: 34.35 | G14: 15.27 | H14: 71.49
... A194: Monaco | B194: MCO | C194: 0.18 | D194: 0.02 | E194: 1.57 | F194: 1.68 | G194: 0.44 | H194: 5.25

Sheet CGT
A1: Country | B1: CGT | C1: Providing headline number | D1: https://taxsummaries.pwc.com/quick-charts/capital-gains-tax-cgt-rates
A2: Switzerland | B2: 0
A3: Luxembourg
A4: United States
A5: Singapore
A6: Iceland
A7: Denmark
A8: Australia
A9: Hong Kong (China)
A10: Netherlands
A11: Norway
A12: United Kingdom
A13: United Arab Emirates
A14: New Zealand
... A107: Nigeria

Sheet Sheet1
A1: Country | B1: Col_2025 | C1: Sal_2025
A2: Us Virgin Islands | B2: 75.4 | C2: =VLOOKUP(A2, Country!A:B, 2, FALSE) -> #N/A
A3: Switzerland | B3: 74.8 | C3: =VLOOKUP(A3, Country!A:B, 2, FALSE) -> 6862.91
A4: Singapore | B4: 73.7 | C4: =VLOOKUP(A4, Country!A:B, 2, FALSE) -> 4106.34
A5: Bahamas | B5: 66.1 | C5: =VLOOKUP(A5, Country!A:B, 2, FALSE) -> #N/A
A6: Iceland | B6: 65.9 | C6: =VLOOKUP(A6, Country!A:B, 2, FALSE) -> 4076.16
A7: Hong Kong (China) | B7: 65.7 | C7: =VLOOKUP(A7, Country!A:B, 2, FALSE) -> 3852.5
A8: Guernsey | B8: 57.1 | C8: =VLOOKUP(A8, Country!A:B, 2, FALSE) -> #N/A
A9: Luxembourg | B9: 54.8 | C9: =VLOOKUP(A9, Country!A:B, 2, FALSE) -> 5379.43
A10: United States | B10: 54.3 | C10: =VLOOKUP(A10, Country!A:B, 2, FALSE) -> 4269.48
A11: Papua New Guinea | B11: 53.7 | C11: =VLOOKUP(A11, Country!A:B, 2, FALSE) -> #N/A
A12: Ireland | B12: 50.6 | C12: =VLOOKUP(A12, Country!A:B, 2, FALSE) -> 3441.52
A13: Norway | B13: 49.4 | C13: =VLOOKUP(A13, Country!A:B, 2, FALSE) -> 3645.41
... A140: Pakistan | B140: 11.2 | C140: =VLOOKUP(A140, Country!A:B, 2, FALSE) -> 181.6

Sheet Sheet2
A1: Country | B1: Sal | C1: Col_2025 | D1: % Sal Germ | E1: % Sal Col
A2: Switzerland | B2: 6862.91 | C2: =VLOOKUP(A2, Sheet1!A:B, 2, FALSE) -> 74.8 | D2: =(B2-B$18)*100/B$18 -> 108.78439 | E2: =(C2-C$18)*100/C$18 -> 76.415094
A3: Luxembourg | B3: 5379.43 | C3: =VLOOKUP(A3, Sheet1!A:B, 2, FALSE) -> 54.8 | D3: =(B3-B$18)*100/B$18 -> 63.65376 | E3: =(C3-C$18)*100/C$18 -> 29.245283
A4: United States | B4: 4269.48 | C4: =VLOOKUP(A4, Sheet1!A:B, 2, FALSE) -> 54.3 | D4: =(B4-B$18)*100/B$18 -> 29.886708 | E4: =(C4-C$18)*100/C$18 -> 28.066038
A5: Singapore | B5: 4106.34 | C5: =VLOOKUP(A5, Sheet1!A:B, 2, FALSE) -> 73.7 | D5: =(B5-B$18)*100/B$18 -> 24.92364 | E5: =(C5-C$18)*100/C$18 -> 73.820755
A6: Iceland | B6: 4076.16 | C6: =VLOOKUP(A6, Sheet1!A:B, 2, FALSE) -> 65.9 | D6: =(B6-B$18)*100/B$18 -> 24.0055 | E6: =(C6-C$18)*100/C$18 -> 55.424528
A7: Denmark | B7: 4005.27 | C7: =VLOOKUP(A7, Sheet1!A:B, 2, FALSE) -> 48.6 | D7: =(B7-B$18)*100/B$18 -> 21.848875 | E7: =(C7-C$18)*100/C$18 -> 14.622642
A8: Australia | B8: 3945.23 | C8: =VLOOKUP(A8, Sheet1!A:B, 2, FALSE) -> 47.1 | D8: =(B8-B$18)*100/B$18 -> 20.02233 | E8: =(C8-C$18)*100/C$18 -> 11.084906
A9: Hong Kong (China) | B9: 3852.5 | C9: =VLOOKUP(A9, Sheet1!A:B, 2, FALSE) -> 65.7 | D9: =(B9-B$18)*100/B$18 -> 17.201285 | E9: =(C9-C$18)*100/C$18 -> 54.95283
A10: Netherlands | B10: 3829.17 | C10: =VLOOKUP(A10, Sheet1!A:B, 2, FALSE) -> 47.9 | D10: =(B10-B$18)*100/B$18 -> 16.491537 | E10: =(C10-C$18)*100/C$18 -> 12.971698
A11: Norway | B11: 3645.41 | C11: =VLOOKUP(A11, Sheet1!A:B, 2, FALSE) -> 49.4 | D11: =(B11-B$18)*100/B$18 -> 10.901165 | E11: =(C11-C$18)*100/C$18 -> 16.509434
A12: United Kingdom | B12: 3572.87 | C12: =VLOOKUP(A12, Sheet1!A:B, 2, FALSE) -> 46.3 | D12: =(B12-B$18)*100/B$18 -> 8.6943427 | E12: =(C12-C$18)*100/C$18 -> 9.1981132
A13: United Arab Emirates | B13: 3520.47 | C13: =VLOOKUP(A13, Sheet1!A:B, 2, FALSE) -> 47.8 | D13: =(B13-B$18)*100/B$18 -> 7.1002227 | E13: =(C13-C$18)*100/C$18 -> 12.735849
... A107: Nigeria | B107: 122.75 | C107: =VLOOKUP(A107, Sheet1!A:B, 2, FALSE) -> 24.4 | D107: =(B107-B$18)*100/B$18 -> -96.265683 | E107: =(C107-C$18)*100/C$18 -> -42.45283
