Workbook

Sheet Country
A1: Country | B1: Cost of Living | C1: Safety | D1: Healthcare | E1: Political Stability | F1: Pollution | G1: Climate | H1: English Proficiency | I1: Openness | J1: Natural Scenery | K1: Natural Disaster | L1: Life Expectancy at 60
A2: Switzerland | B2: =VLOOKUP(A2, Sheet1!A:B, 2, FALSE()) -> 81.5 | C2: =VLOOKUP(A2, Safety!A:B, 2, FALSE()) -> 89.234036 | D2: =VLOOKUP(A2, Health!A:B, 2, FALSE()) -> 68.8 | E2: =VLOOKUP(A2, Political!A:H, 8, FALSE()) -> 87.26 | F2: =VLOOKUP(A2, Pollution!A:B, 2, FALSE()) -> 8.32 | G2: =VLOOKUP(A2, Climate!A:B, 2, FALSE()) -> 2357 | H2: =VLOOKUP(A2, English!A:C, 3, FALSE()) -> 564 | I2: =VLOOKUP(A2, Openness!A:C, 2, FALSE()) -> 46 | J2: =VLOOKUP(A2, Scenic!A:B, 2, FALSE()) -> 4 | K2: =VLOOKUP(A2, Disaster!A:H, 4, FALSE()) -> 0.16 | L2: =VLOOKUP(A2, LifeExp60!A:B, 2, FALSE()) -> 27.468
A3: Luxembourg | B3: =VLOOKUP(A3, Sheet1!A:B, 2, FALSE()) -> 64.2 | C3: =VLOOKUP(A3, Safety!A:B, 2, FALSE()) -> 78.643759 | D3: =VLOOKUP(A3, Health!A:B, 2, FALSE()) -> 70.7 | E3: =VLOOKUP(A3, Political!A:H, 8, FALSE()) -> 87.306667 | F3: =VLOOKUP(A3, Pollution!A:B, 2, FALSE()) -> 7.43 | G3: =VLOOKUP(A3, Climate!A:B, 2, FALSE()) -> 2218 | H3: =VLOOKUP(A3, English!A:C, 3, FALSE()) -> 576 | I3: =VLOOKUP(A3, Openness!A:C, 2, FALSE()) -> 38 | J3: =VLOOKUP(A3, Scenic!A:B, 2, FALSE()) -> 40 | K3: =VLOOKUP(A3, Disaster!A:H, 4, FALSE()) -> 0.06 | L3: =VLOOKUP(A3, LifeExp60!A:B, 2, FALSE()) -> 26.17
A4: Iceland | B4: =VLOOKUP(A4, Sheet1!A:B, 2, FALSE()) -> 74.8 | C4: =VLOOKUP(A4, Safety!A:B, 2, FALSE()) -> 80.944996 | D4: =VLOOKUP(A4, Health!A:B, 2, FALSE()) -> 68.7 | E4: =VLOOKUP(A4, Political!A:H, 8, FALSE()) -> 83.221667 | F4: =VLOOKUP(A4, Pollution!A:B, 2, FALSE()) -> 4.93 | G4: =VLOOKUP(A4, Climate!A:B, 2, FALSE()) -> 1012 | H4: =VLOOKUP(A4, English!A:C, 3, FALSE()) -> #N/A | I4: =VLOOKUP(A4, Openness!A:C, 2, FALSE()) -> #N/A | J4: =VLOOKUP(A4, Scenic!A:B, 2, FALSE()) -> 8 | K4: =VLOOKUP(A4, Disaster!A:H, 4, FALSE()) -> 0.71 | L4: =VLOOKUP(A4, LifeExp60!A:B, 2, FALSE()) -> 25.948
A5: Singapore | B5: =VLOOKUP(A5, Sheet1!A:B, 2, FALSE()) -> 80.5 | C5: =VLOOKUP(A5, Safety!A:B, 2, FALSE()) -> 98.465492 | D5: =VLOOKUP(A5, Health!A:B, 2, FALSE()) -> 71.9 | E5: =VLOOKUP(A5, Political!A:H, 8, FALSE()) -> 83.598333 | F5: =VLOOKUP(A5, Pollution!A:B, 2, FALSE()) -> 15.14 | G5: =VLOOKUP(A5, Climate!A:B, 2, FALSE()) -> 1186 | H5: =VLOOKUP(A5, English!A:C, 3, FALSE()) -> 609 | I5: =VLOOKUP(A5, Openness!A:C, 2, FALSE()) -> 30 | J5: =VLOOKUP(A5, Scenic!A:B, 2, FALSE()) -> 33 | K5: =VLOOKUP(A5, Disaster!A:H, 4, FALSE()) -> 0.17 | L5: =VLOOKUP(A5, LifeExp60!A:B, 2, FALSE()) -> 27.825
A6: Norway | B6: =VLOOKUP(A6, Sheet1!A:B, 2, FALSE()) -> 59.3 | C6: =VLOOKUP(A6, Safety!A:B, 2, FALSE()) -> 87.460889 | D6: =VLOOKUP(A6, Health!A:B, 2, FALSE()) -> 75.1 | E6: =VLOOKUP(A6, Political!A:H, 8, FALSE()) -> 87.685 | F6: =VLOOKUP(A6, Pollution!A:B, 2, FALSE()) -> 5.52 | G6: =VLOOKUP(A6, Climate!A:B, 2, FALSE()) -> 1821 | H6: =VLOOKUP(A6, English!A:C, 3, FALSE()) -> 613 | I6: =VLOOKUP(A6, Openness!A:C, 2, FALSE()) -> 52 | J6: =VLOOKUP(A6, Scenic!A:B, 2, FALSE()) -> 7 | K6: =VLOOKUP(A6, Disaster!A:H, 4, FALSE()) -> 1.1 | L6: =VLOOKUP(A6, LifeExp60!A:B, 2, FALSE()) -> 26.522
A7: United States | B7: =VLOOKUP(A7, Sheet1!A:B, 2, FALSE()) -> 54.8 | C7: =VLOOKUP(A7, Safety!A:B, 2, FALSE()) -> 56.040163 | D7: =VLOOKUP(A7, Health!A:B, 2, FALSE()) -> 66.9 | E7: =VLOOKUP(A7, Political!A:H, 8, FALSE()) -> 69.428333 | F7: =VLOOKUP(A7, Pollution!A:B, 2, FALSE()) -> 6.97 | G7: =VLOOKUP(A7, Climate!A:B, 2, FALSE()) -> 2418 | H7: 700 | I7: =VLOOKUP(A7, Openness!A:C, 2, FALSE()) -> 28 | J7: =VLOOKUP(A7, Scenic!A:B, 2, FALSE()) -> 51 | K7: =VLOOKUP(A7, Disaster!A:H, 4, FALSE()) -> 39.78 | L7: =VLOOKUP(A7, LifeExp60!A:B, 2, FALSE()) -> 25.365
A8: Denmark | B8: =VLOOKUP(A8, Sheet1!A:B, 2, FALSE()) -> 54.8 | C8: =VLOOKUP(A8, Safety!A:B, 2, FALSE()) -> 85.964139 | D8: =VLOOKUP(A8, Health!A:B, 2, FALSE()) -> 74.4 | E8: =VLOOKUP(A8, Political!A:H, 8, FALSE()) -> 88.74 | F8: =VLOOKUP(A8, Pollution!A:B, 2, FALSE()) -> 7.5 | G8: =VLOOKUP(A8, Climate!A:B, 2, FALSE()) -> 1961 | H8: =VLOOKUP(A8, English!A:C, 3, FALSE()) -> 611 | I8: =VLOOKUP(A8, Openness!A:C, 2, FALSE()) -> 45 | J8: =VLOOKUP(A8, Scenic!A:B, 2, FALSE()) -> 25 | K8: =VLOOKUP(A8, Disaster!A:H, 4, FALSE()) -> 0.18 | L8: =VLOOKUP(A8, LifeExp60!A:B, 2, FALSE()) -> 25.735
A9: Qatar | B9: =VLOOKUP(A9, Sheet1!A:B, 2, FALSE()) -> 44.1 | C9: =VLOOKUP(A9, Safety!A:B, 2, FALSE()) -> 98.465492 | D9: =VLOOKUP(A9, Health!A:B, 2, FALSE()) -> 73.8 | E9: =VLOOKUP(A9, Political!A:H, 8, FALSE()) -> 66.15 | F9: =VLOOKUP(A9, Pollution!A:B, 2, FALSE()) -> 107.76 | G9: =VLOOKUP(A9, Climate!A:B, 2, FALSE()) -> 1851 | H9: =VLOOKUP(A9, English!A:C, 3, FALSE()) -> 469 | I9: =VLOOKUP(A9, Openness!A:C, 2, FALSE()) -> 22 | J9: =VLOOKUP(A9, Scenic!A:B, 2, FALSE()) -> 69 | K9: =VLOOKUP(A9, Disaster!A:H, 4, FALSE()) -> 0.17 | L9: =VLOOKUP(A9, LifeExp60!A:B, 2, FALSE()) -> 25.209
A10: Australia | B10: =VLOOKUP(A10, Sheet1!A:B, 2, FALSE()) -> 53.9 | C10: =VLOOKUP(A10, Safety!A:B, 2, FALSE()) -> 85.802312 | D10: =VLOOKUP(A10, Health!A:B, 2, FALSE()) -> 71.8 | E10: =VLOOKUP(A10, Political!A:H, 8, FALSE()) -> 83.875 | F10: =VLOOKUP(A10, Pollution!A:B, 2, FALSE()) -> 6.41 | G10: =VLOOKUP(A10, Climate!A:B, 2, FALSE()) -> 3315 | H10: 700 | I10: =VLOOKUP(A10, Openness!A:C, 2, FALSE()) -> 20 | J10: =VLOOKUP(A10, Scenic!A:B, 2, FALSE()) -> 9 | K10: =VLOOKUP(A10, Disaster!A:H, 4, FALSE()) -> 32.11 | L10: =VLOOKUP(A10, LifeExp60!A:B, 2, FALSE()) -> 27.677
A11: Netherlands | B11: =VLOOKUP(A11, Sheet1!A:B, 2, FALSE()) -> 56 | C11: =VLOOKUP(A11, Safety!A:B, 2, FALSE()) -> 87.918709 | D11: =VLOOKUP(A11, Health!A:B, 2, FALSE()) -> 77.6 | E11: =VLOOKUP(A11, Political!A:H, 8, FALSE()) -> 83.676667 | F11: =VLOOKUP(A11, Pollution!A:B, 2, FALSE()) -> 8.59 | G11: =VLOOKUP(A11, Climate!A:B, 2, FALSE()) -> 2185 | H11: =VLOOKUP(A11, English!A:C, 3, FALSE()) -> 624 | I11: =VLOOKUP(A11, Openness!A:C, 2, FALSE()) -> 41 | J11: =VLOOKUP(A11, Scenic!A:B, 2, FALSE()) -> 21 | K11: =VLOOKUP(A11, Disaster!A:H, 4, FALSE()) -> 2.17 | L11: =VLOOKUP(A11, LifeExp60!A:B, 2, FALSE()) -> 25.753
A12: Israel | B12: =VLOOKUP(A12, Sheet1!A:B, 2, FALSE()) -> 64.8 | C12: =VLOOKUP(A12, Safety!A:B, 2, FALSE()) -> 77.796346 | D12: =VLOOKUP(A12, Health!A:B, 2, FALSE()) -> 73.5 | E12: =VLOOKUP(A12, Political!A:H, 8, FALSE()) -> 67.205 | F12: =VLOOKUP(A12, Pollution!A:B, 2, FALSE()) -> 21.9 | G12: =VLOOKUP(A12, Climate!A:B, 2, FALSE()) -> 2897 | H12: =VLOOKUP(A12, English!A:C, 3, FALSE()) -> 524 | I12: =VLOOKUP(A12, Openness!A:C, 2, FALSE()) -> #N/A | J12: =VLOOKUP(A12, Scenic!A:B, 2, FALSE()) -> 87 | K12: =VLOOKUP(A12, Disaster!A:H, 4, FALSE()) -> 1.2 | L12: =VLOOKUP(A12, LifeExp60!A:B, 2, FALSE()) -> 26.441
A13: United Kingdom | B13: =VLOOKUP(A13, Sheet1!A:B, 2, FALSE()) -> 50.8 | C13: =VLOOKUP(A13, Safety!A:B, 2, FALSE()) -> 82.729812 | D13: =VLOOKUP(A13, Health!A:B, 2, FALSE()) -> 72.4 | E13: =VLOOKUP(A13, Political!A:H, 8, FALSE()) -> 78.106667 | F13: =VLOOKUP(A13, Pollution!A:B, 2, FALSE()) -> 9.46 | G13: =VLOOKUP(A13, Climate!A:B, 2, FALSE()) -> 2219 | H13: 700 | I13: =VLOOKUP(A13, Openness!A:C, 2, FALSE()) -> 42 | J13: =VLOOKUP(A13, Scenic!A:B, 2, FALSE()) -> 45 | K13: =VLOOKUP(A13, Disaster!A:H, 4, FALSE()) -> 2.6 | L13: =VLOOKUP(A13, LifeExp60!A:B, 2, FALSE()) -> 25.596
A14: Ireland | B14: =VLOOKUP(A14, Sheet1!A:B, 2, FALSE()) -> 57.4 | C14: =VLOOKUP(A14, Safety!A:B, 2, FALSE()) -> 88.427504 | D14: =VLOOKUP(A14, Health!A:B, 2, FALSE()) -> 51.3 | E14: =VLOOKUP(A14, Political!A:H, 8, FALSE()) -> 82.925 | F14: =VLOOKUP(A14, Pollution!A:B, 2, FALSE()) -> 7.51 | G14: =VLOOKUP(A14, Climate!A:B, 2, FALSE()) -> 2068 | H14: 700 | I14: =VLOOKUP(A14, Openness!A:C, 2, FALSE()) -> 29 | J14: =VLOOKUP(A14, Scenic!A:B, 2, FALSE()) -> 11 | K14: =VLOOKUP(A14, Disaster!A:H, 4, FALSE()) -> 1.48 | L14: =VLOOKUP(A14, LifeExp60!A:B, 2, FALSE()) -> 26.357
A15: Germany | B15: =VLOOKUP(A15, Sheet1!A:B, 2, FALSE()) -> 47 | C15: =VLOOKUP(A15, Safety!A:B, 2, FALSE()) -> 85.105906 | D15: =VLOOKUP(A15, Health!A:B, 2, FALSE()) -> 71.3 | E15: =VLOOKUP(A15, Political!A:H, 8, FALSE()) -> 80.246667 | F15: =VLOOKUP(A15, Pollution!A:B, 2, FALSE()) -> 8.81 | G15: =VLOOKUP(A15, Climate!A:B, 2, FALSE()) -> 2327 | H15: =VLOOKUP(A15, English!A:C, 3, FALSE()) -> 615 | I15: =VLOOKUP(A15, Openness!A:C, 2, FALSE()) -> 51 | J15: =VLOOKUP(A15, Scenic!A:B, 2, FALSE()) -> 50 | K15: =VLOOKUP(A15, Disaster!A:H, 4, FALSE()) -> 1.95 | L15: =VLOOKUP(A15, LifeExp60!A:B, 2, FALSE()) -> 25.805
A16: Hong Kong (China) | B16: =VLOOKUP(A16, Sheet1!A:B, 2, FALSE()) -> 68.5 | C16: =VLOOKUP(A16, Safety!A:B, 2, FALSE()) -> 92.659493 | D16: =VLOOKUP(A16, Health!A:B, 2, FALSE()) -> 66.5 | E16: =VLOOKUP(A16, Political!A:H, 8, FALSE()) -> 74.946667 | F16: =VLOOKUP(A16, Pollution!A:B, 2, FALSE()) -> #N/A | G16: =VLOOKUP(A16, Climate!A:B, 2, FALSE()) -> #N/A | H16: =VLOOKUP(A16, English!A:C, 3, FALSE()) -> 538 | I16: =VLOOKUP(A16, Openness!A:C, 2, FALSE()) -> 27 | J16: =VLOOKUP(A16, Scenic!A:B, 2, FALSE()) -> #N/A | K16: =VLOOKUP(A16, Disaster!A:H, 4, FALSE()) -> #N/A | L16: =VLOOKUP(A16, LifeExp60!A:B, 2, FALSE()) -> 29.811
A17: Kuwait | B17: =VLOOKUP(A17, Sheet1!A:B, 2, FALSE()) -> 33.3 | C17: =VLOOKUP(A17, Safety!A:B, 2, FALSE()) -> 94.868153 | D17: =VLOOKUP(A17, Health!A:B, 2, FALSE()) -> 58.6 | E17: =VLOOKUP(A17, Political!A:H, 8, FALSE()) -> 58.123333 | F17: =VLOOKUP(A17, Pollution!A:B, 2, FALSE()) -> 62.35 | G17: =VLOOKUP(A17, Climate!A:B, 2, FALSE()) -> 2087 | H17: =VLOOKUP(A17, English!A:C, 3, FALSE()) -> 455 | I17: =VLOOKUP(A17, Openness!A:C, 2, FALSE()) -> 53 | J17: =VLOOKUP(A17, Scenic!A:B, 2, FALSE()) -> 88 | K17: =VLOOKUP(A17, Disaster!A:H, 4, FALSE()) -> 1.01 | L17: =VLOOKUP(A17, LifeExp60!A:B, 2, FALSE()) -> 23.704
A18: Austria | B18: =VLOOKUP(A18, Sheet1!A:B, 2, FALSE()) -> 49.3 | C18: =VLOOKUP(A18, Safety!A:B, 2, FALSE()) -> 85.531019 | D18: =VLOOKUP(A18, Health!A:B, 2, FALSE()) -> 77.5 | E18: =VLOOKUP(A18, Political!A:H, 8, FALSE()) -> 79.438333 | F18: =VLOOKUP(A18, Pollution!A:B, 2, FALSE()) -> 10.03 | G18: =VLOOKUP(A18, Climate!A:B, 2, FALSE()) -> 2382 | H18: =VLOOKUP(A18, English!A:C, 3, FALSE()) -> 616 | I18: =VLOOKUP(A18, Openness!A:C, 2, FALSE()) -> 49 | J18: =VLOOKUP(A18, Scenic!A:B, 2, FALSE()) -> 10 | K18: =VLOOKUP(A18, Disaster!A:H, 4, FALSE()) -> 0.16 | L18: =VLOOKUP(A18, LifeExp60!A:B, 2, FALSE()) -> 26.2
A19: Sweden | B19: =VLOOKUP(A19, Sheet1!A:B, 2, FALSE()) -> 44.7 | C19: =VLOOKUP(A19, Safety!A:B, 2, FALSE()) -> 82.427912 | D19: =VLOOKUP(A19, Health!A:B, 2, FALSE()) -> 68.1 | E19: =VLOOKUP(A19, Political!A:H, 8, FALSE()) -> 85.838333 | F19: =VLOOKUP(A19, Pollution!A:B, 2, FALSE()) -> 5.26 | G19: =VLOOKUP(A19, Climate!A:B, 2, FALSE()) -> 1962 | H19: =VLOOKUP(A19, English!A:C, 3, FALSE()) -> 609 | I19: =VLOOKUP(A19, Openness!A:C, 2, FALSE()) -> 48 | J19: =VLOOKUP(A19, Scenic!A:B, 2, FALSE()) -> 14 | K19: =VLOOKUP(A19, Disaster!A:H, 4, FALSE()) -> 1.07 | L19: =VLOOKUP(A19, LifeExp60!A:B, 2, FALSE()) -> 26.737
A20: Belgium | B20: =VLOOKUP(A20, Sheet1!A:B, 2, FALSE()) -> 47.2 | C20: =VLOOKUP(A20, Safety!A:B, 2, FALSE()) -> 83.157031 | D20: =VLOOKUP(A20, Health!A:B, 2, FALSE()) -> 75.7 | E20: =VLOOKUP(A20, Political!A:H, 8, FALSE()) -> 77.208333 | F20: =VLOOKUP(A20, Pollution!A:B, 2, FALSE()) -> 8.45 | G20: =VLOOKUP(A20, Climate!A:B, 2, FALSE()) -> 2389 | H20: =VLOOKUP(A20, English!A:C, 3, FALSE()) -> 608 | I20: =VLOOKUP(A20, Openness!A:C, 2, FALSE()) -> 31 | J20: =VLOOKUP(A20, Scenic!A:B, 2, FALSE()) -> 47 | K20: =VLOOKUP(A20, Disaster!A:H, 4, FALSE()) -> 1.79 | L20: =VLOOKUP(A20, LifeExp60!A:B, 2, FALSE()) -> 26.429
A21: Canada | B21: =VLOOKUP(A21, Sheet1!A:B, 2, FALSE()) -> 46.6 | C21: =VLOOKUP(A21, Safety!A:B, 2, FALSE()) -> 74.887989 | D21: =VLOOKUP(A21, Health!A:B, 2, FALSE()) -> 68.6 | E21: =VLOOKUP(A21, Political!A:H, 8, FALSE()) -> 82.791667 | F21: =VLOOKUP(A21, Pollution!A:B, 2, FALSE()) -> 6.55 | G21: =VLOOKUP(A21, Climate!A:B, 2, FALSE()) -> 2015 | H21: 700 | I21: =VLOOKUP(A21, Openness!A:C, 2, FALSE()) -> 39 | J21: =VLOOKUP(A21, Scenic!A:B, 2, FALSE()) -> 18 | K21: =VLOOKUP(A21, Disaster!A:H, 4, FALSE()) -> 26.08 | L21: =VLOOKUP(A21, LifeExp60!A:B, 2, FALSE()) -> 27.137
A22: Finland | B22: =VLOOKUP(A22, Sheet1!A:B, 2, FALSE()) -> 46.3 | C22: =VLOOKUP(A22, Safety!A:B, 2, FALSE()) -> 84.266946 | D22: =VLOOKUP(A22, Health!A:B, 2, FALSE()) -> 77.5 | E22: =VLOOKUP(A22, Political!A:H, 8, FALSE()) -> 88.296667 | F22: =VLOOKUP(A22, Pollution!A:B, 2, FALSE()) -> 4.57 | G22: =VLOOKUP(A22, Climate!A:B, 2, FALSE()) -> 1737 | H22: =VLOOKUP(A22, English!A:C, 3, FALSE()) -> 603 | I22: =VLOOKUP(A22, Openness!A:C, 2, FALSE()) -> 50 | J22: =VLOOKUP(A22, Scenic!A:B, 2, FALSE()) -> 17 | K22: =VLOOKUP(A22, Disaster!A:H, 4, FALSE()) -> 0.51 | L22: =VLOOKUP(A22, LifeExp60!A:B, 2, FALSE()) -> 26.546
A23: United Arab Emirates | B23: =VLOOKUP(A23, Sheet1!A:B, 2, FALSE()) -> 46.8 | C23: =VLOOKUP(A23, Safety!A:B, 2, FALSE()) -> 87.891524 | D23: =VLOOKUP(A23, Health!A:B, 2, FALSE()) -> 70.8 | E23: =VLOOKUP(A23, Political!A:H, 8, FALSE()) -> 68.031667 | F23: =VLOOKUP(A23, Pollution!A:B, 2, FALSE()) -> 57.19 | G23: =VLOOKUP(A23, Climate!A:B, 2, FALSE()) -> 1720 | H23: =VLOOKUP(A23, English!A:C, 3, FALSE()) -> 487 | I23: =VLOOKUP(A23, Openness!A:C, 2, FALSE()) -> 16 | J23: =VLOOKUP(A23, Scenic!A:B, 2, FALSE()) -> 60 | K23: =VLOOKUP(A23, Disaster!A:H, 4, FALSE()) -> 4.72 | L23: =VLOOKUP(A23, LifeExp60!A:B, 2, FALSE()) -> 25.574
A24: France | B24: =VLOOKUP(A24, Sheet1!A:B, 2, FALSE()) -> 45.7 | C24: =VLOOKUP(A24, Safety!A:B, 2, FALSE()) -> 80.369769 | D24: =VLOOKUP(A24, Health!A:B, 2, FALSE()) -> 76.9 | E24: =VLOOKUP(A24, Political!A:H, 8, FALSE()) -> 73.39 | F24: =VLOOKUP(A24, Pollution!A:B, 2, FALSE()) -> 8.23 | G24: =VLOOKUP(A24, Climate!A:B, 2, FALSE()) -> 2710 | H24: =VLOOKUP(A24, English!A:C, 3, FALSE()) -> 539 | I24: =VLOOKUP(A24, Openness!A:C, 2, FALSE()) -> 34 | J24: =VLOOKUP(A24, Scenic!A:B, 2, FALSE()) -> 20 | K24: =VLOOKUP(A24, Disaster!A:H, 4, FALSE()) -> 2.63 | L24: =VLOOKUP(A24, LifeExp60!A:B, 2, FALSE()) -> 28.253
A25: New Zealand | B25: =VLOOKUP(A25, Sheet1!A:B, 2, FALSE()) -> 43.9 | C25: =VLOOKUP(A25, Safety!A:B, 2, FALSE()) -> 79.288776 | D25: =VLOOKUP(A25, Health!A:B, 2, FALSE()) -> 68.1 | E25: =VLOOKUP(A25, Political!A:H, 8, FALSE()) -> 87.281667 | F25: =VLOOKUP(A25, Pollution!A:B, 2, FALSE()) -> 6.88 | G25: =VLOOKUP(A25, Climate!A:B, 2, FALSE()) -> 3149 | H25: 700 | I25: =VLOOKUP(A25, Openness!A:C, 2, FALSE()) -> 21 | J25: =VLOOKUP(A25, Scenic!A:B, 2, FALSE()) -> 2 | K25: =VLOOKUP(A25, Disaster!A:H, 4, FALSE()) -> 18.1 | L25: =VLOOKUP(A25, LifeExp60!A:B, 2, FALSE()) -> 26.177
A26: Puerto Rico | B26: =VLOOKUP(A26, Sheet1!A:B, 2, FALSE()) -> 45.8 | C26: =VLOOKUP(A26, Safety!A:B, 2, FALSE()) -> 36.118545 | D26: =VLOOKUP(A26, Health!A:B, 2, FALSE()) -> 58.7 | E26: =VLOOKUP(A26, Political!A:H, 8, FALSE()) -> 61.305 | F26: =VLOOKUP(A26, Pollution!A:B, 2, FALSE()) -> 7.84 | G26: =VLOOKUP(A26, Climate!A:B, 2, FALSE()) -> #N/A | H26: 700 | I26: =VLOOKUP(A26, Openness!A:C, 2, FALSE()) -> #N/A | J26: =VLOOKUP(A26, Scenic!A:B, 2, FALSE()) -> #N/A | K26: =VLOOKUP(A26, Disaster!A:H, 4, FALSE()) -> #N/A | L26: =VLOOKUP(A26, LifeExp60!A:B, 2, FALSE()) -> 27.581
A27: Oman | B27: =VLOOKUP(A27, Sheet1!A:B, 2, FALSE()) -> 30.2 | C27: =VLOOKUP(A27, Safety!A:B, 2, FALSE()) -> 97.006799 | D27: =VLOOKUP(A27, Health!A:B, 2, FALSE()) -> 62.7 | E27: =VLOOKUP(A27, Political!A:H, 8, FALSE()) -> 61.008333 | F27: =VLOOKUP(A27, Pollution!A:B, 2, FALSE()) -> 46.86 | G27: =VLOOKUP(A27, Climate!A:B, 2, FALSE()) -> 1762 | H27: =VLOOKUP(A27, English!A:C, 3, FALSE()) -> 407 | I27: =VLOOKUP(A27, Openness!A:C, 2, FALSE()) -> 12 | J27: =VLOOKUP(A27, Scenic!A:B, 2, FALSE()) -> 79 | K27: =VLOOKUP(A27, Disaster!A:H, 4, FALSE()) -> 7.04 | L27: =VLOOKUP(A27, LifeExp60!A:B, 2, FALSE()) -> 24.615
A28: South Korea | B28: =VLOOKUP(A28, Sheet1!A:B, 2, FALSE()) -> 37 | C28: =VLOOKUP(A28, Safety!A:B, 2, FALSE()) -> 91.030496 | D28: =VLOOKUP(A28, Health!A:B, 2, FALSE()) -> 83 | E28: =VLOOKUP(A28, Political!A:H, 8, FALSE()) -> 76.058333 | F28: =VLOOKUP(A28, Pollution!A:B, 2, FALSE()) -> 21.89 | G28: =VLOOKUP(A28, Climate!A:B, 2, FALSE()) -> 1890 | H28: =VLOOKUP(A28, English!A:C, 3, FALSE()) -> 522 | I28: =VLOOKUP(A28, Openness!A:C, 2, FALSE()) -> 36 | J28: =VLOOKUP(A28, Scenic!A:B, 2, FALSE()) -> 70 | K28: =VLOOKUP(A28, Disaster!A:H, 4, FALSE()) -> 9.83 | L28: =VLOOKUP(A28, LifeExp60!A:B, 2, FALSE()) -> 28.35
A29: Bahrain | B29: =VLOOKUP(A29, Sheet1!A:B, 2, FALSE()) -> 35.1 | C29: =VLOOKUP(A29, Safety!A:B, 2, FALSE()) -> 95.883764 | D29: =VLOOKUP(A29, Health!A:B, 2, FALSE()) -> #N/A | E29: =VLOOKUP(A29, Political!A:H, 8, FALSE()) -> 56.581667 | F29: =VLOOKUP(A29, Pollution!A:B, 2, FALSE()) -> 56.57 | G29: =VLOOKUP(A29, Climate!A:B, 2, FALSE()) -> #N/A | H29: =VLOOKUP(A29, English!A:C, 3, FALSE()) -> #N/A | I29: =VLOOKUP(A29, Openness!A:C, 2, FALSE()) -> 18 | J29: =VLOOKUP(A29, Scenic!A:B, 2, FALSE()) -> 84 | K29: =VLOOKUP(A29, Disaster!A:H, 4, FALSE()) -> 0.12 | L29: =VLOOKUP(A29, LifeExp60!A:B, 2, FALSE()) -> 24.508
A30: Japan | B30: =VLOOKUP(A30, Sheet1!A:B, 2, FALSE()) -> 32.1 | C30: =VLOOKUP(A30, Safety!A:B, 2, FALSE()) -> 95.257801 | D30: =VLOOKUP(A30, Health!A:B, 2, FALSE()) -> 79.9 | E30: =VLOOKUP(A30, Political!A:H, 8, FALSE()) -> 82.961667 | F30: =VLOOKUP(A30, Pollution!A:B, 2, FALSE()) -> 11.45 | G30: =VLOOKUP(A30, Climate!A:B, 2, FALSE()) -> 2190 | H30: =VLOOKUP(A30, English!A:C, 3, FALSE()) -> 446 | I30: =VLOOKUP(A30, Openness!A:C, 2, FALSE()) -> 35 | J30: =VLOOKUP(A30, Scenic!A:B, 2, FALSE()) -> 23 | K30: =VLOOKUP(A30, Disaster!A:H, 4, FALSE()) -> 43.35 | L30: =VLOOKUP(A30, LifeExp60!A:B, 2, FALSE()) -> 29.482
A31: Spain | B31: =VLOOKUP(A31, Sheet1!A:B, 2, FALSE()) -> 38.1 | C31: =VLOOKUP(A31, Safety!A:B, 2, FALSE()) -> 87.918709 | D31: =VLOOKUP(A31, Health!A:B, 2, FALSE()) -> 76.7 | E31: =VLOOKUP(A31, Political!A:H, 8, FALSE()) -> 69.885 | F31: =VLOOKUP(A31, Pollution!A:B, 2, FALSE()) -> 10.08 | G31: =VLOOKUP(A31, Climate!A:B, 2, FALSE()) -> 3001 | H31: =VLOOKUP(A31, English!A:C, 3, FALSE()) -> 540 | I31: =VLOOKUP(A31, Openness!A:C, 2, FALSE()) -> 11 | J31: =VLOOKUP(A31, Scenic!A:B, 2, FALSE()) -> 5 | K31: =VLOOKUP(A31, Disaster!A:H, 4, FALSE()) -> 7.54 | L31: =VLOOKUP(A31, LifeExp60!A:B, 2, FALSE()) -> 27.982
A32: Estonia | B32: =VLOOKUP(A32, Sheet1!A:B, 2, FALSE()) -> 39.2 | C32: =VLOOKUP(A32, Safety!A:B, 2, FALSE()) -> 78.598371 | D32: =VLOOKUP(A32, Health!A:B, 2, FALSE()) -> 75.4 | E32: =VLOOKUP(A32, Political!A:H, 8, FALSE()) -> 81.496667 | F32: =VLOOKUP(A32, Pollution!A:B, 2, FALSE()) -> 5.92 | G32: =VLOOKUP(A32, Climate!A:B, 2, FALSE()) -> 1908 | H32: =VLOOKUP(A32, English!A:C, 3, FALSE()) -> 561 | I32: =VLOOKUP(A32, Openness!A:C, 2, FALSE()) -> #N/A | J32: =VLOOKUP(A32, Scenic!A:B, 2, FALSE()) -> 62 | K32: =VLOOKUP(A32, Disaster!A:H, 4, FALSE()) -> 0.53 | L32: =VLOOKUP(A32, LifeExp60!A:B, 2, FALSE()) -> 25.402
A33: Italy | B33: =VLOOKUP(A33, Sheet1!A:B, 2, FALSE()) -> 41.9 | C33: =VLOOKUP(A33, Safety!A:B, 2, FALSE()) -> 89.655495 | D33: =VLOOKUP(A33, Health!A:B, 2, FALSE()) -> 64.8 | E33: =VLOOKUP(A33, Political!A:H, 8, FALSE()) -> 69.39 | F33: =VLOOKUP(A33, Pollution!A:B, 2, FALSE()) -> 14.29 | G33: =VLOOKUP(A33, Climate!A:B, 2, FALSE()) -> 2758 | H33: =VLOOKUP(A33, English!A:C, 3, FALSE()) -> 513 | I33: =VLOOKUP(A33, Openness!A:C, 2, FALSE()) -> 33 | J33: =VLOOKUP(A33, Scenic!A:B, 2, FALSE()) -> 3 | K33: =VLOOKUP(A33, Disaster!A:H, 4, FALSE()) -> 8.86 | L33: =VLOOKUP(A33, LifeExp60!A:B, 2, FALSE()) -> 27.372
A34: Saudi Arabia | B34: =VLOOKUP(A34, Sheet1!A:B, 2, FALSE()) -> 30.3 | C34: =VLOOKUP(A34, Safety!A:B, 2, FALSE()) -> 84.818876 | D34: =VLOOKUP(A34, Health!A:B, 2, FALSE()) -> 62.2 | E34: =VLOOKUP(A34, Political!A:H, 8, FALSE()) -> 58.971667 | F34: =VLOOKUP(A34, Pollution!A:B, 2, FALSE()) -> 73.52 | G34: =VLOOKUP(A34, Climate!A:B, 2, FALSE()) -> 1986 | H34: =VLOOKUP(A34, English!A:C, 3, FALSE()) -> 404 | I34: =VLOOKUP(A34, Openness!A:C, 2, FALSE()) -> 25 | J34: =VLOOKUP(A34, Scenic!A:B, 2, FALSE()) -> 83 | K34: =VLOOKUP(A34, Disaster!A:H, 4, FALSE()) -> 4.32 | L34: =VLOOKUP(A34, LifeExp60!A:B, 2, FALSE()) -> 23.887
A35: Cyprus | B35: =VLOOKUP(A35, Sheet1!A:B, 2, FALSE()) -> 42.4 | C35: =VLOOKUP(A35, Safety!A:B, 2, FALSE()) -> 84.558876 | D35: =VLOOKUP(A35, Health!A:B, 2, FALSE()) -> 56.6 | E35: =VLOOKUP(A35, Political!A:H, 8, FALSE()) -> 69.46 | F35: =VLOOKUP(A35, Pollution!A:B, 2, FALSE()) -> 16.07 | G35: =VLOOKUP(A35, Climate!A:B, 2, FALSE()) -> 2823 | H35: =VLOOKUP(A35, English!A:C, 3, FALSE()) -> 537 | I35: =VLOOKUP(A35, Openness!A:C, 2, FALSE()) -> 17 | J35: =VLOOKUP(A35, Scenic!A:B, 2, FALSE()) -> 35 | K35: =VLOOKUP(A35, Disaster!A:H, 4, FALSE()) -> 0.68 | L35: =VLOOKUP(A35, LifeExp60!A:B, 2, FALSE()) -> 25.234
A36: Malta | B36: =VLOOKUP(A36, Sheet1!A:B, 2, FALSE()) -> 43.3 | C36: =VLOOKUP(A36, Safety!A:B, 2, FALSE()) -> 89.728948 | D36: =VLOOKUP(A36, Health!A:B, 2, FALSE()) -> 53.3 | E36: =VLOOKUP(A36, Political!A:H, 8, FALSE()) -> 68.53 | F36: =VLOOKUP(A36, Pollution!A:B, 2, FALSE()) -> 10.81 | G36: =VLOOKUP(A36, Climate!A:B, 2, FALSE()) -> #N/A | H36: =VLOOKUP(A36, English!A:C, 3, FALSE()) -> #N/A | I36: =VLOOKUP(A36, Openness!A:C, 2, FALSE()) -> 32 | J36: =VLOOKUP(A36, Scenic!A:B, 2, FALSE()) -> #N/A | K36: =VLOOKUP(A36, Disaster!A:H, 4, FALSE()) -> 0.15 | L36: =VLOOKUP(A36, LifeExp60!A:B, 2, FALSE()) -> 27.533
A37: Czech Republic | B37: =VLOOKUP(A37, Sheet1!A:B, 2, FALSE()) -> 37 | C37: =VLOOKUP(A37, Safety!A:B, 2, FALSE()) -> 86.894635 | D37: =VLOOKUP(A37, Health!A:B, 2, FALSE()) -> 75.6 | E37: =VLOOKUP(A37, Political!A:H, 8, FALSE()) -> 76.043333 | F37: =VLOOKUP(A37, Pollution!A:B, 2, FALSE()) -> 12.75 | G37: =VLOOKUP(A37, Climate!A:B, 2, FALSE()) -> 2342 | H37: =VLOOKUP(A37, English!A:C, 3, FALSE()) -> 582 | I37: =VLOOKUP(A37, Openness!A:C, 2, FALSE()) -> 47 | J37: =VLOOKUP(A37, Scenic!A:B, 2, FALSE()) -> 53 | K37: =VLOOKUP(A37, Disaster!A:H, 4, FALSE()) -> 0.1 | L37: =VLOOKUP(A37, LifeExp60!A:B, 2, FALSE()) -> 24.623
A38: Taiwan | B38: =VLOOKUP(A38, Sheet1!A:B, 2, FALSE()) -> 32.6 | C38: =VLOOKUP(A38, Safety!A:B, 2, FALSE()) -> #N/A | D38: =VLOOKUP(A38, Health!A:B, 2, FALSE()) -> 87.1 | E38: =VLOOKUP(A38, Political!A:H, 8, FALSE()) -> 78.288333 | F38: =VLOOKUP(A38, Pollution!A:B, 2, FALSE()) -> #N/A | G38: =VLOOKUP(A38, Climate!A:B, 2, FALSE()) -> 2218 | H38: =VLOOKUP(A38, English!A:C, 3, FALSE()) -> #N/A | I38: =VLOOKUP(A38, Openness!A:C, 2, FALSE()) -> #N/A | J38: =VLOOKUP(A38, Scenic!A:B, 2, FALSE()) -> #N/A | K38: =VLOOKUP(A38, Disaster!A:H, 4, FALSE()) -> #N/A | L38: =VLOOKUP(A38, LifeExp60!A:B, 2, FALSE()) -> #N/A
... A153: Libya | B153: =VLOOKUP(A153, Sheet1!A:B, 2, FALSE()) -> 12.7 | C153: =VLOOKUP(A153, Safety!A:B, 2, FALSE()) -> #N/A | D153: =VLOOKUP(A153, Health!A:B, 2, FALSE()) -> #N/A | E153: =VLOOKUP(A153, Political!A:H, 8, FALSE()) -> 27.013333 | F153: =VLOOKUP(A153, Pollution!A:B, 2, FALSE()) -> 20.01 | G153: =VLOOKUP(A153, Climate!A:B, 2, FALSE()) -> #N/A | H153: =VLOOKUP(A153, English!A:C, 3, FALSE()) -> 395 | I153: =VLOOKUP(A153, Openness!A:C, 2, FALSE()) -> #N/A | J153: =VLOOKUP(A153, Scenic!A:B, 2, FALSE()) -> #N/A | K153: =VLOOKUP(A153, Disaster!A:H, 4, FALSE()) -> 4.75 | L153: =VLOOKUP(A153, LifeExp60!A:B, 2, FALSE()) -> 18.553

Sheet Safety
A1: Country | B1: Safety_homicide_score | C1: Homicide_rate_per_100k | D1: Year | E1: Active (tab 1 uses col B). Source: UNODC via Our World in Data (homicide-rate-unodc), latest year per country, downloaded Oct 2026. Score = 100*(1-LN(1+rate)/LN(1+max rate)): 100 = no homicides, higher = safer; log scale because rates are very skewed (median ~2.6, max ~76). Years older than 2015 flagged. | G1: Country | H1: Safety_2026MY | J1: Country | K1: Safety index_2025 | L1: Numbeo. Active: 2026 Mid-Year (A:B). | M1: Numbeo perceived safety (2026 Mid-Year and 2025) - kept for reference, no longer used.
A2: American Samoa | B2: =100*(1-LN(1+C2)/LN(1+MAX($C$2:$C$209))) -> 100 | C2: 0 | D2: 2019 | G2: Andorra | H2: 86.5 | J2: Andorra | K2: 84.7
A3: Gibraltar | B3: =100*(1-LN(1+C3)/LN(1+MAX($C$2:$C$209))) -> 100 | C3: 0 | D3: 2024 | G3: United Arab Emirates | H3: 86.4 | J3: United Arab Emirates | K3: 84.5
A4: Isle Of Man | B4: =100*(1-LN(1+C4)/LN(1+MAX($C$2:$C$209))) -> 100 | C4: 0 | D4: 2016 | G4: Qatar | H4: 84.8 | J4: Qatar | K4: 84.2
A5: Monaco | B5: =100*(1-LN(1+C5)/LN(1+MAX($C$2:$C$209))) -> 100 | C5: 0 | D5: 2008 | E5: old data (latest year < 2015) | G5: Taiwan | H5: 82.9 | J5: Taiwan | K5: 82.9
A6: Montserrat | B6: =100*(1-LN(1+C6)/LN(1+MAX($C$2:$C$209))) -> 100 | C6: 0 | D6: 2018 | G6: Macao (China) | H6: 81.8 | J6: Oman | K6: 81.7
A7: Saint Helena | B7: =100*(1-LN(1+C7)/LN(1+MAX($C$2:$C$209))) -> 100 | C7: 0 | D7: 2009 | E7: old data (latest year < 2015) | G7: Oman | H7: 81.7 | J7: Isle Of Man | K7: 79
A8: San Marino | B8: =100*(1-LN(1+C8)/LN(1+MAX($C$2:$C$209))) -> 100 | C8: 0 | D8: 2011 | E8: old data (latest year < 2015) | G8: Isle Of Man | H8: 80.3 | J8: Hong Kong (China) | K8: 78.5
A9: Tuvalu | B9: =100*(1-LN(1+C9)/LN(1+MAX($C$2:$C$209))) -> 100 | C9: 0 | D9: 2019 | G9: Hong Kong (China) | H9: 78.2 | J9: Armenia | K9: 77.9
A10: Vatican | B10: =100*(1-LN(1+C10)/LN(1+MAX($C$2:$C$209))) -> 100 | C10: 0 | D10: 2023 | G10: Armenia | H10: 78 | J10: Singapore | K10: 77.4
A11: Jersey | B11: =100*(1-LN(1+C11)/LN(1+MAX($C$2:$C$209))) -> 100 | C11: 0 | D11: 2010 | E11: Channel Islands figure (2010) | G11: Japan | H11: 77.8 | J11: Japan | K11: 77.1
A12: Guernsey | B12: =100*(1-LN(1+C12)/LN(1+MAX($C$2:$C$209))) -> 100 | C12: 0 | D12: 2010 | E12: Channel Islands figure (2010) | G12: Bahrain | H12: 77.7 | J12: Monaco | K12: 76.7
A13: Singapore | B13: =100*(1-LN(1+C13)/LN(1+MAX($C$2:$C$209))) -> 98.465492 | C13: 0.069 | D13: 2023 | G13: Singapore | H13: 77.7 | J13: Estonia | K13: 76.3
A14: Qatar | B14: =100*(1-LN(1+C14)/LN(1+MAX($C$2:$C$209))) -> 98.465492 | C14: 0.069 | D14: 2022 | G14: China | H14: 77 | J14: Slovenia | K14: 76.2
A15: Oman | B15: =100*(1-LN(1+C15)/LN(1+MAX($C$2:$C$209))) -> 97.006799 | C15: 0.139 | D15: 2023 | G15: Saudi Arabia | H15: 76.8 | J15: Saudi Arabia | K15: 76.1
A16: Bahrain | B16: =100*(1-LN(1+C16)/LN(1+MAX($C$2:$C$209))) -> 95.883764 | C16: 0.196 | D16: 2022 | G16: Estonia | H16: 76.5 | J16: China | K16: 76
A17: Japan | B17: =100*(1-LN(1+C17)/LN(1+MAX($C$2:$C$209))) -> 95.257801 | C17: 0.229 | D17: 2023 | G17: Slovenia | H17: 75.5 | J17: Bahrain | K17: 75.5
A18: Kuwait | B18: =100*(1-LN(1+C18)/LN(1+MAX($C$2:$C$209))) -> 94.868153 | C18: 0.25 | D18: 2020 | G18: Croatia | H18: 74.8 | J18: South Korea | K18: 75.1
A19: Indonesia | B19: =100*(1-LN(1+C19)/LN(1+MAX($C$2:$C$209))) -> 93.895502 | C19: 0.304 | D19: 2022 | G19: Iceland | H19: 74.5 | J19: Croatia | K19: 74.5
A20: Vanuatu | B20: =100*(1-LN(1+C20)/LN(1+MAX($C$2:$C$209))) -> 93.355169 | C20: 0.335 | D20: 2020 | G20: Monaco | H20: 74.5 | J20: Iceland | K20: 74.3
A21: French Polynesia | B21: =100*(1-LN(1+C21)/LN(1+MAX($C$2:$C$209))) -> 92.743214 | C21: 0.371 | D21: 2009 | E21: old data (latest year < 2015) | G21: Finland | H21: 73.7 | J21: Denmark | K21: 74
A22: Hong Kong (China) | B22: =100*(1-LN(1+C22)/LN(1+MAX($C$2:$C$209))) -> 92.659493 | C22: 0.376 | D22: 2023 | G22: Rwanda | H22: 73.6 | J22: Georgia | K22: 73.7
A23: South Korea | B23: =100*(1-LN(1+C23)/LN(1+MAX($C$2:$C$209))) -> 91.030496 | C23: 0.477 | D23: 2023 | G23: Czech Republic | H23: 73.3 | J23: Czech Republic | K23: 73.5
A24: Brunei | B24: =100*(1-LN(1+C24)/LN(1+MAX($C$2:$C$209))) -> 90.890784 | C24: 0.486 | D24: 2013 | E24: old data (latest year < 2015) | G24: Denmark | H24: 73.2 | J24: Switzerland | K24: 73.5
A25: China | B25: =100*(1-LN(1+C25)/LN(1+MAX($C$2:$C$209))) -> 90.644485 | C25: 0.502 | D25: 2020 | G25: Georgia | H25: 73.1 | J25: Finland | K25: 73.2
A26: Macao (China) | B26: =100*(1-LN(1+C26)/LN(1+MAX($C$2:$C$209))) -> 89.773132 | C26: 0.56 | D26: 2023 | G26: Uzbekistan | H26: 72.7 | J26: Rwanda | K26: 73.1
A27: Malta | B27: =100*(1-LN(1+C27)/LN(1+MAX($C$2:$C$209))) -> 89.728948 | C27: 0.563 | D27: 2023 | G27: Netherlands | H27: 72.3 | J27: Netherlands | K27: 73.1
A28: Slovenia | B28: =100*(1-LN(1+C28)/LN(1+MAX($C$2:$C$209))) -> 89.684848 | C28: 0.566 | D28: 2023 | G28: Switzerland | H28: 71.9 | J28: Uzbekistan | K28: 72.1
A29: Italy | B29: =100*(1-LN(1+C29)/LN(1+MAX($C$2:$C$209))) -> 89.655495 | C29: 0.568 | D29: 2023 | G29: Poland | H29: 71.3 | J29: Poland | K29: 71
A30: Switzerland | B30: =100*(1-LN(1+C30)/LN(1+MAX($C$2:$C$209))) -> 89.234036 | C30: 0.597 | D30: 2023 | G30: Cayman Islands | H30: 71 | J30: Brunei | K30: 70.7
A31: Maldives | B31: =100*(1-LN(1+C31)/LN(1+MAX($C$2:$C$209))) -> 88.976273 | C31: 0.615 | D31: 2019 | G31: Austria | H31: 70.8 | J31: Austria | K31: 70.5
A32: Palestine | B32: =100*(1-LN(1+C32)/LN(1+MAX($C$2:$C$209))) -> 88.876806 | C32: 0.622 | D32: 2022 | G32: South Korea | H32: 70.3 | J32: Cayman Islands | K32: 69.2
A33: Ireland | B33: =100*(1-LN(1+C33)/LN(1+MAX($C$2:$C$209))) -> 88.427504 | C33: 0.654 | D33: 2023 | G33: Brunei | H33: 70.1 | J33: Slovakia | K33: 69
A34: Croatia | B34: =100*(1-LN(1+C34)/LN(1+MAX($C$2:$C$209))) -> 88.247452 | C34: 0.667 | D34: 2023 | G34: Slovakia | H34: 69.1 | J34: Azerbaijan | K34: 68.2
A35: Spain | B35: =100*(1-LN(1+C35)/LN(1+MAX($C$2:$C$209))) -> 87.918709 | C35: 0.691 | D35: 2023 | G35: Azerbaijan | H35: 68.5 | J35: Israel | K35: 68.2
A36: Netherlands | B36: =100*(1-LN(1+C36)/LN(1+MAX($C$2:$C$209))) -> 87.918709 | C36: 0.691 | D36: 2023 | G36: Israel | H36: 68.2 | J36: Portugal | K36: 67.9
... A75: Luxembourg | B75: =100*(1-LN(1+C75)/LN(1+MAX($C$2:$C$209))) -> 78.643759 | C75: 1.531 | D75: 2022 | G75: Kazakhstan | H75: 54.8 | J75: Zambia | K75: 54.4
A76: Vietnam | B76: =100*(1-LN(1+C76)/LN(1+MAX($C$2:$C$209))) -> 78.607442 | C76: 1.535 | D76: 2011 | E76: old data (latest year < 2015) | G76: Canada | H76: 54.4 | J76: Canada | K76: 54.3
A77: Estonia | B77: =100*(1-LN(1+C77)/LN(1+MAX($C$2:$C$209))) -> 78.598371 | C77: 1.536 | D77: 2023 | G77: Sudan | H77: 54.4 | J77: Indonesia | K77: 54
A78: Israel | B78: =100*(1-LN(1+C78)/LN(1+MAX($C$2:$C$209))) -> 77.796346 | C78: 1.626 | D78: 2022 | G78: Egypt | H78: 54 | J78: Greece | K78: 53.6
...

Sheet Health
A1: Country | B1: Healthcare_2026MY | D1: Country | E1: Healthcare_2025 | F1: Numbeo. Active: 2026 Mid-Year (A:B).
A2: Taiwan | B2: 87.1 | D2: Taiwan | E2: 86.5
A3: South Korea | B3: 83 | D3: South Korea | E3: 82.8
A4: Japan | B4: 79.9 | D4: Japan | E4: 80
A5: Ecuador | B5: 78.2 | D5: Netherlands | E5: 79.3
A6: Netherlands | B6: 77.6 | D6: Denmark | E6: 78.4
A7: Thailand | B7: 77.6 | D7: Austria | E7: 77.9
A8: Austria | B8: 77.5 | D8: France | E8: 77.7
A9: Finland | B9: 77.5 | D9: Finland | E9: 77.5
A10: France | B10: 76.9 | D10: Thailand | E10: 77.5
A11: Spain | B11: 76.7 | D11: Spain | E11: 77.3
A12: Belgium | B12: 75.7 | D12: Ecuador | E12: 77.1
A13: Czech Republic | B13: 75.6 | D13: Belgium | E13: 75.9
... A98: Iraq | B98: 47.2 | D98: Venezuela | E98: 38.7
A99: Morocco | B99: 46.8
A100: Bangladesh | B100: 42.1
A101: Venezuela | B101: 39.4
A102: Syria | B102: 35.7

Sheet Political
A1: Country | B1: cc | C1: ge | D1: pv | E1: rl | F1: rq | G1: va | H1: Average | I1: Political stability_2025: World Bank WGI 2026 release, data year 2025, "Governance score (0-100)" averaged over 6 dimensions. NOTE: WB dropped percentile ranks; this scale is not directly comparable with the 2023 block. | K1: Country | L1: cc | M1: ge | N1: pv | O1: rl | P1: rq | Q1: va | R1: Average | S1: Political stability_2023 (percentile ranks). Korea rows corrected.
A2: Afghanistan | B2: 21.7 | C2: 12.03 | D2: 29.81 | E2: 28.13 | F2: 30.76 | G2: 17.66 | H2: =AVERAGE(B2:G2) -> 23.348333 | K2: Afghanistan | L2: 13.679245 | M2: 1.4150944 | N2: 1.421801 | O2: 5.1886792 | P2: 9.4339619 | Q2: 1.9607843 | R2: 5.5165943
A3: Albania | B3: 41.97 | C3: 61.98 | D3: 67.18 | E3: 57.99 | F3: 60.67 | G3: 60.04 | H3: =AVERAGE(B3:G3) -> 58.305 | K3: Albania | L3: 43.396225 | M3: 60.377357 | N3: 51.658768 | O3: 45.754719 | P3: 58.490566 | Q3: 53.92157 | R3: 52.266534
A4: Algeria | B4: 37.33 | C4: 48.39 | D4: 54 | E4: 47.88 | F4: 41.91 | G4: 37.81 | H4: =AVERAGE(B4:G4) -> 44.553333 | K4: Algeria | L4: 30.188679 | M4: 27.35849 | N4: 23.22275 | O4: 26.415094 | P4: 16.037735 | Q4: 22.058823 | R4: 24.213595
A5: American Samoa | B5: 71.84 | C5: 70.14 | D5: 90.14 | E5: 80.85 | F5: 61.94 | H5: =AVERAGE(B5:G5) -> 74.982 | K5: American Samoa | L5: 87.735847 | M5: 73.113205 | N5: 91.94313 | O5: 85.377357 | P5: 68.396225 | R5: 81.313153
A6: Andorra | B6: 71.84 | C6: 80.58 | D6: 93 | E6: 84.61 | F6: 70.13 | G6: 72.29 | H6: =AVERAGE(B6:G6) -> 78.741667 | K6: Andorra | L6: 87.735847 | M6: 91.037735 | N6: 98.578201 | O6: 91.509438 | P6: 89.622643 | Q6: 78.92157 | R6: 89.567572
A7: Angola | B7: 34.28 | C7: 37.84 | D7: 57.94 | E7: 40.1 | F7: 42.69 | G7: 39.36 | H7: =AVERAGE(B7:G7) -> 42.035 | K7: Angola | L7: 29.245283 | M7: 14.622642 | N7: 32.227489 | O7: 14.622642 | P7: 22.64151 | Q7: 27.941177 | R7: 23.550124
A8: Anguilla | B8: 71.84 | C8: 74.91 | D8: 90.36 | E8: 69.2 | F8: 70.13 | H8: =AVERAGE(B8:G8) -> 75.288 | K8: Anguilla | L8: 87.735847 | M8: 87.264153 | N8: 91.94313 | O8: 75 | P8: 79.245285 | R8: 84.237683
A9: Antigua and Barbuda | B9: 59.9 | C9: 61.36 | D9: 86.78 | E9: 68.01 | F9: 66.17 | G9: 67.81 | H9: =AVERAGE(B9:G9) -> 68.338333 | K9: Antigua and Barbuda | L9: 62.264153 | M9: 63.679245 | N9: 80.568718 | O9: 59.905659 | P9: 70.28302 | Q9: 70.098038 | R9: 67.799805
A10: Argentina | B10: 40.26 | C10: 57.99 | D10: 68.45 | E10: 56.94 | F10: 53.89 | G10: 65.94 | H10: =AVERAGE(B10:G10) -> 57.245 | K10: Argentina | L10: 41.981133 | M10: 36.320755 | N10: 41.706161 | O10: 37.735847 | P10: 35.377357 | Q10: 63.235294 | R10: 42.726091
A11: Armenia | B11: 50.31 | C11: 47.49 | D11: 58.04 | E11: 54.26 | F11: 59.24 | G11: 59.94 | H11: =AVERAGE(B11:G11) -> 54.88 | K11: Armenia | L11: 57.07547 | M11: 43.867924 | N11: 17.061611 | O11: 49.056602 | P11: 52.830189 | Q11: 50.490196 | R11: 45.063665
A12: Aruba | B12: 65.57 | C12: 70.86 | D12: 87.78 | E12: 78.83 | F12: 72.28 | G12: 78.16 | H12: =AVERAGE(B12:G12) -> 75.58 | K12: Aruba | L12: 75.471695 | M12: 78.301888 | N12: 97.630333 | O12: 87.264153 | P12: 80.188683 | Q12: 80.392159 | R12: 83.208151
A13: Australia | B13: 85.12 | C13: 88.19 | D13: 79.29 | E13: 82.67 | F13: 84.23 | G13: 83.75 | H13: =AVERAGE(B13:G13) -> 83.875 | K13: Australia | L13: 95.754715 | M13: 93.867928 | N13: 79.62085 | O13: 91.981133 | P13: 99.528305 | Q13: 96.07843 | R13: 92.805227
A14: Austria | B14: 74.3 | C14: 83.94 | D14: 74.92 | E14: 85.83 | F14: 73.87 | G14: 83.77 | H14: =AVERAGE(B14:G14) -> 79.438333 | K14: Austria | L14: 83.490562 | M14: 89.622643 | N14: 71.56398 | O14: 97.169815 | P14: 90.094337 | Q14: 93.627449 | R14: 87.594798
A15: Azerbaijan | B15: 32.35 | C15: 54.91 | D15: 63.97 | E15: 51.1 | F15: 56.38 | G15: 29.73 | H15: =AVERAGE(B15:G15) -> 48.073333 | K15: Azerbaijan | L15: 12.264151 | M15: 50.471699 | N15: 18.00948 | O15: 29.245283 | P15: 49.056602 | Q15: 9.3137255 | R15: 28.060157
A16: Bahamas | B16: 69.11 | C16: 65.63 | D16: 83.48 | E16: 62.41 | F16: 53.97 | G16: 69.32 | H16: =AVERAGE(B16:G16) -> 67.32 | K16: Bahamas, The | L16: 88.20755 | M16: 61.792454 | N16: 84.834122 | O16: 55.660378 | P16: 51.886791 | Q16: 74.019608 | R16: 69.40015
A17: Bahrain | B17: 53.72 | C17: 60.95 | D17: 59.77 | E17: 61.59 | F17: 72.76 | G17: 30.7 | H17: =AVERAGE(B17:G17) -> 56.581667 | K17: Bahrain | L17: 59.433964 | M17: 74.528305 | N17: 29.383886 | O17: 65.56604 | P17: 83.962265 | Q17: 11.274509 | R17: 54.024828
A18: Bangladesh | B18: 28.2 | C18: 43.24 | D18: 49.11 | E18: 43.64 | F18: 39.35 | G18: 44.49 | H18: =AVERAGE(B18:G18) -> 41.338333 | K18: Bangladesh | L18: 14.622642 | M18: 26.886793 | N18: 15.639811 | O18: 33.490566 | P18: 18.867924 | Q18: 27.450981 | R18: 22.826453
A19: Barbados | B19: 72.8 | C19: 64.85 | D19: 88.05 | E19: 70.49 | F19: 62.28 | G19: 77.65 | H19: =AVERAGE(B19:G19) -> 72.686667 | K19: Barbados | L19: 89.622643 | M19: 64.15094 | N19: 93.83886 | O19: 62.264153 | P19: 67.452827 | Q19: 87.254906 | R19: 77.430721
A20: Belarus | B20: 36.5 | C20: 36 | D20: 62.57 | E20: 38.41 | F20: 33.82 | G20: 25.81 | H20: =AVERAGE(B20:G20) -> 38.851667 | K20: Belarus | L20: 26.886793 | M20: 15.094339 | N20: 18.483412 | O20: 11.320755 | P20: 7.5471697 | Q20: 3.9215686 | R20: 13.875673
... A23: Benin | B23: 43.78 | C23: 48.92 | D23: 58.62 | E23: 51.12 | F23: 50.4 | G23: 51.47 | H23: =AVERAGE(B23:G23) -> 50.718333 | K23: Benin | L23: 52.830189 | M23: 42.452831 | N23: 31.753555 | O23: 33.018867 | P23: 40.566036 | Q23: 40.196079 | R23: 40.13626
A24: Bermuda | B24: 71.84 | C24: 82.38 | D24: 84.54 | E24: 71.94 | F24: 66.04 | H24: =AVERAGE(B24:G24) -> 75.348 | K24: Bermuda | L24: 87.735847 | M24: 87.264153 | N24: 86.729858 | O24: 75 | P24: 79.245285 | R24: 83.195029
A25: Bhutan | B25: 77.76 | C25: 66.79 | D25: 90.02 | E25: 70.52 | F25: 53.89 | G25: 61.6 | H25: =AVERAGE(B25:G25) -> 70.096667 | K25: Bhutan | L25: 91.037735 | M25: 69.339622 | N25: 83.412323 | O25: 72.64151 | P25: 36.792454 | Q25: 54.901962 | R25: 68.020934
A26: Bolivia | B26: 24.13 | C26: 39.72 | D26: 62.74 | E26: 36.42 | F26: 34.46 | G26: 54.54 | H26: =AVERAGE(B26:G26) -> 42.001667 | K26: Bolivia | L26: 21.698112 | M26: 29.245283 | N26: 35.071091 | O26: 11.792453 | P26: 11.792453 | Q26: 39.215687 | R26: 24.802513
A27: Bosnia And Herzegovina | B27: 38.35 | C27: 42.6 | D27: 59.65 | E27: 53.03 | F27: 48.55 | G27: 53.03 | H27: =AVERAGE(B27:G27) -> 49.201667 | K27: Bosnia and Herzegovina | L27: 30.660378 | M27: 15.566038 | N27: 31.279621 | O27: 39.622643 | P27: 46.698112 | Q27: 38.235294 | R27: 33.677014
A28: Botswana | B28: 59.94 | C28: 61.23 | D28: 84.51 | E28: 63.26 | F28: 61.6 | G28: 64.99 | H28: =AVERAGE(B28:G28) -> 65.921667 | K28: Botswana | L28: 73.584908 | M28: 66.981133 | N28: 87.203789 | O28: 61.320755 | P28: 66.981133 | Q28: 62.745098 | R28: 69.802802
A29: Brazil | B29: 40.36 | C29: 51.61 | D29: 58.87 | E29: 50.63 | F29: 47.89 | G29: 65.47 | H29: =AVERAGE(B29:G29) -> 52.471667 | K29: Brazil | L29: 34.433964 | M29: 32.07547 | N29: 28.43602 | O29: 41.981133 | P29: 40.094341 | Q29: 59.803921 | R29: 39.470808
A30: Brunei | B30: 68.07 | C30: 70.61 | D30: 91.88 | E30: 69.73 | F30: 72.07 | G30: 40.22 | H30: =AVERAGE(B30:G30) -> 68.763333 | K30: Brunei Darussalam | L30: 88.679245 | M30: 90.094337 | N30: 96.682465 | O30: 79.245285 | P30: 80.660378 | Q30: 28.921568 | R30: 77.380546
A31: Bulgaria | B31: 42.22 | C31: 54.91 | D31: 69.9 | E31: 57.88 | F31: 61.34 | G31: 62.65 | H31: =AVERAGE(B31:G31) -> 58.15 | K31: Bulgaria | L31: 50 | M31: 53.301888 | N31: 55.450237 | O31: 53.773586 | P31: 65.56604 | Q31: 60.294117 | R31: 56.397645
A32: Burkina Faso | B32: 43.51 | C32: 36.15 | D32: 34.09 | E32: 43.48 | F32: 44.63 | G32: 35.63 | H32: =AVERAGE(B32:G32) -> 39.581667 | K32: Burkina Faso | L32: 49.528301 | M32: 21.226416 | N32: 5.6872039 | O32: 24.528301 | P32: 34.905659 | Q32: 25.490196 | R32: 26.894346
A33: Burundi | B33: 17 | C33: 26.7 | D33: 43.99 | E33: 35.02 | F33: 40.55 | G33: 29.49 | H33: =AVERAGE(B33:G33) -> 32.125 | K33: Burundi | L33: 3.3018868 | M33: 11.320755 | N33: 12.796208 | O33: 10.849056 | P33: 15.566038 | Q33: 11.764706 | R33: 10.933108
A34: Cambodia | B34: 22.56 | C34: 44.14 | D34: 71.47 | E34: 41.35 | F34: 45.4 | G34: 27.51 | H34: =AVERAGE(B34:G34) -> 42.071667 | K34: Cambodia | L34: 9.4339619 | M34: 38.207546 | N34: 47.867298 | O34: 23.584906 | P34: 25.471699 | Q34: 12.745098 | R34: 26.218418
A35: Cameroon | B35: 23.75 | C35: 36.07 | D35: 35.96 | E35: 38.97 | F35: 41.95 | G35: 34.68 | H35: =AVERAGE(B35:G35) -> 35.23 | K35: Cameroon | L35: 13.207547 | M35: 17.452829 | N35: 11.374408 | O35: 16.509434 | P35: 19.339622 | Q35: 19.607843 | R35: 16.248614
A36: Canada | B36: 80.21 | C36: 88.31 | D36: 79.8 | E36: 82.97 | F36: 80.3 | G36: 85.16 | H36: =AVERAGE(B36:G36) -> 82.791667 | K36: Canada | L36: 94.811317 | M36: 91.981133 | N36: 76.303314 | O36: 90.094337 | P36: 94.811317 | Q36: 95.098038 | R36: 90.516576
... A68: French Guiana | B68: 72.14 | C68: 80.32 | D68: 75.05 | E68: 74.18 | F68: 74.28 | G68: 78.16 | H68: =AVERAGE(B68:G68) -> 75.688333 | K68: France | L68: 83.962265 | M68: 83.018867 | N68: 55.924171 | O68: 84.905663 | P68: 85.377357 | Q68: 86.764709 | R68: 79.992172
A69: French Polynesia | B69: 44.06 | D69: 75.7 | E69: 69.33 | G69: 73.82 | H69: =AVERAGE(B69:G69) -> 65.7275 | K69: French Guiana | L69: 80.188683 | M69: 89.15094 | N69: 53.08057 | O69: 83.962265 | P69: 83.490562 | Q69: 91.666664 | R69: 80.256614
A70: Gabon | B70: 32.4 | C70: 41.06 | D70: 67.65 | E70: 41.77 | F70: 42.93 | G70: 42.56 | H70: =AVERAGE(B70:G70) -> 44.728333 | K70: Gabon | L70: 17.924528 | M70: 23.113207 | N70: 33.649288 | O70: 20.754717 | P70: 25 | Q70: 24.019608 | R70: 24.076891
A71: Gambia, The | B71: 37.74 | C71: 43.5 | D71: 66.23 | E71: 52.12 | F71: 44.4 | G71: 53.9 | H71: =AVERAGE(B71:G71) -> 49.648333 | K71: Gambia, The | L71: 46.226414 | M71: 29.716982 | N71: 45.971565 | O71: 38.207546 | P71: 28.301888 | Q71: 45.588234 | R71: 39.002105
A72: Georgia | B72: 45.22 | C72: 59.53 | D72: 56.93 | E72: 60.2 | F72: 66.23 | G72: 51.14 | H72: =AVERAGE(B72:G72) -> 56.541667 | K72: Georgia | L72: 71.226418 | M72: 77.830185 | N72: 33.175354 | O72: 55.188679 | P72: 79.71698 | Q72: 48.039215 | R72: 60.862805
A73: Germany | B73: 81.85 | C73: 82.84 | D73: 69.26 | E73: 85.07 | F73: 76.43 | G73: 86.03 | H73: =AVERAGE(B73:G73) -> 80.246667 | K73: Germany | L73: 94.339622 | M73: 85.377357 | N73: 66.350708 | O73: 92.92453 | P73: 91.981133 | Q73: 94.607841 | R73: 87.596865
...

Sheet Pollution
A1: Country | B1: PM25_2023 | C1: Year | D1: Active (tab 1 uses col B). PM2.5 mean annual exposure, micrograms per m3, population-weighted, modelled (satellite + ground monitors). Source: Global Burden of Disease Study 2023, IHME, via World Bank (2026), processed by Our World in Data. Lower = better. | F1: Country | G1: Pollution_2026MY | H1: Exp Pollution Index | J1: Country | K1: Pollution_2025 | L1: Exp Pollution Index | M1: Numbeo. Active: 2026 Mid-Year (A:B). | N1: Numbeo pollution (perception survey) 2026 Mid-Year and 2025 - kept for reference, no longer used.
A2: Greenland | B2: 1.64 | C2: 2023 | F2: Cameroon | G2: 91.9 | H2: 166 | J2: Cameroon | K2: 93.7 | L2: 169.8
A3: Northern Mariana Islands | B3: 2.68 | C3: 2023 | F3: Myanmar | G3: 89.6 | H3: 161.8 | J3: Myanmar | K3: 89.8 | L3: 162.2
A4: Guam | B4: 3.47 | C4: 2023 | F4: Lebanon | G4: 89.2 | H4: 159.5 | J4: Lebanon | K4: 89.4 | L4: 159.8
A5: Micronesia (country) | B5: 3.52 | C5: 2023 | F5: Mongolia | G5: 88 | H5: 160.9 | J5: Nigeria | K5: 88.2 | L5: 157.5
A6: Kiribati | B6: 3.87 | C6: 2023 | F6: Nigeria | G6: 87.2 | H6: 155.7 | J6: Mongolia | K6: 87.8 | L6: 160.4
A7: Marshall Islands | B7: 4.1 | C7: 2023 | F7: Ghana | G7: 86.3 | H7: 154.5 | J7: Ghana | K7: 87 | L7: 155.8
A8: American Samoa | B8: 4.33 | C8: 2023 | F8: Bangladesh | G8: 85.2 | H8: 152.2 | J8: Bangladesh | K8: 85.6 | L8: 153
A9: Finland | B9: 4.57 | C9: 2023 | F9: Afghanistan | G9: 84.4 | H9: 150.5 | J9: Afghanistan | K9: 84.4 | L9: 150.5
A10: Samoa | B10: 4.58 | C10: 2023 | F10: Nepal | G10: 84.4 | H10: 150.1 | J10: Vietnam | K10: 84.2 | L10: 150.4
A11: Bermuda | B11: 4.63 | C11: 2023 | F11: Vietnam | G11: 83.7 | H11: 149.4 | J11: Nepal | K11: 84.2 | L11: 149.6
A12: Tonga | B12: 4.69 | C12: 2023 | F12: Peru | G12: 82.7 | H12: 147.2 | J12: Egypt | K12: 82.7 | L12: 146.8
A13: Nauru | B13: 4.84 | C13: 2023 | F13: Egypt | G13: 82.6 | H13: 146.6 | J13: Peru | K13: 82.5 | L13: 146.7
... A114: Venezuela | B114: 19.2 | C114: 2023 | F114: Sweden | G114: 17.1 | H114: 27.1 | J114: Finland | K114: 11.9 | L114: 19.9
A115: Serbia | B115: 19.34 | C115: 2023 | F115: Iceland | G115: 17.1 | H115: 28.7
A116: Cambodia | B116: 19.43 | C116: 2023 | F116: Austria | G116: 16.3 | H116: 27.1
A117: Kazakhstan | B117: 19.6 | C117: 2023 | F117: Estonia | G117: 15.7 | H117: 25.4
A118: Bulgaria | B118: 19.68 | C118: 2023 | F118: Finland | G118: 10.9 | H118: 19.1
A119: Angola | B119: 19.91 | C119: 2023
A120: Libya | B120: 20.01 | C120: 2023
A121: Kyrgyzstan | B121: 20.12 | C121: 2023
A122: Tanzania | B122: 20.17 | C122: 2023
A123: Cape Verde | B123: 20.19 | C123: 2023
A124: Zambia | B124: 20.24 | C124: 2023
A125: Kenya | B125: 20.25 | C125: 2023
A126: Ivory Coast | B126: 20.39 | C126: 2023
A127: Nicaragua | B127: 20.42 | C127: 2023
A128: Indonesia | B128: 20.84 | C128: 2023
A129: Jamaica | B129: 21.65 | C129: 2023
A130: North Korea | B130: 21.78 | C130: 2023
... A208: Qatar | B208: 107.76 | C208: 2023

Sheet Climate
A1: Country | B1: Climate_hours | C1: GeoRank: comfortable outdoor hours per year (static, does not change by year). Collected for the old 106-country list only. | E1: Country | F1: Climate_2025 | G1: Old: Numbeo climate score (0-100), no longer used.
A2: Peru | B2: 4029 | E2: Venezuela | F2: 99.9
A3: Kenya | B3: 3871 | E3: Kenya | F3: 99.8
A4: Zimbabwe | B4: 3684 | E4: Costa Rica | F4: 99.5
A5: South Africa | B5: 3533 | E5: Ecuador | F5: 98.7
A6: Colombia | B6: 3521 | E6: Colombia | F6: 98.4
A7: Morocco | B7: 3506 | E7: Argentina | F7: 98.3
A8: Uganda | B8: 3481 | E8: Uruguay | F8: 98
A9: Chile | B9: 3478 | E9: Peru | F9: 97.7
A10: Mexico | B10: 3462 | E10: Malta | F10: 97.4
A11: Australia | B11: 3315 | E11: Brazil | F11: 97.4
A12: Argentina | B12: 3231 | E12: Portugal | F12: 97.3
A13: Portugal | B13: 3176 | E13: New Zealand | F13: 95.5
... A89: Singapore | B89: 1186 | E89: Kuwait | F89: 20.2
A90: Vietnam | B90: 1139
A91: Panama | B91: 1115
A92: Indonesia | B92: 1023
A93: Iceland | B93: 1012
A94: Philippines | B94: 928
A95: Malaysia | B95: 660
A96: Thailand | B96: 660

Sheet English
A1: Country/Region | B1: Proficiency Band | C1: Score | D1: Band points | E1: Source: https://www.ef.com/wwen/epi/ EF EPI 2025. Tab 1 uses Score (col C). Native-English countries are set to 700 directly on tab 1. | G1: Country/Region | H1: Proficiency Band | I1: Score | J1: Band points | K1: English_2024 (old)
A2: Netherlands | B2: Very high proficiency | C2: 624 | D2: =IF(LEFT(B2,9)="Very high",100,IF(LEFT(B2,4)="High",80,IF(LEFT(B2,8)="Moderate",60,IF(LEFT(B2,3)="Low",40,IF(LEFT(B2,8)="Very low",20))))) -> 100 | G2: Netherlands | H2: Very high proficiency | I2: 636
A3: Croatia | B3: Very high proficiency | C3: 617 | D3: =IF(LEFT(B3,9)="Very high",100,IF(LEFT(B3,4)="High",80,IF(LEFT(B3,8)="Moderate",60,IF(LEFT(B3,3)="Low",40,IF(LEFT(B3,8)="Very low",20))))) -> 100 | G3: Norway | H3: Very high proficiency | I3: 610
A4: Austria | B4: Very high proficiency | C4: 616 | D4: =IF(LEFT(B4,9)="Very high",100,IF(LEFT(B4,4)="High",80,IF(LEFT(B4,8)="Moderate",60,IF(LEFT(B4,3)="Low",40,IF(LEFT(B4,8)="Very low",20))))) -> 100 | G4: Singapore | H4: Very high proficiency | I4: 609
A5: Germany | B5: Very high proficiency | C5: 615 | D5: =IF(LEFT(B5,9)="Very high",100,IF(LEFT(B5,4)="High",80,IF(LEFT(B5,8)="Moderate",60,IF(LEFT(B5,3)="Low",40,IF(LEFT(B5,8)="Very low",20))))) -> 100 | G5: Sweden | H5: Very high proficiency | I5: 608
A6: Norway | B6: Very high proficiency | C6: 613 | D6: =IF(LEFT(B6,9)="Very high",100,IF(LEFT(B6,4)="High",80,IF(LEFT(B6,8)="Moderate",60,IF(LEFT(B6,3)="Low",40,IF(LEFT(B6,8)="Very low",20))))) -> 100 | G6: Croatia | H6: Very high proficiency | I6: 607
A7: Portugal | B7: Very high proficiency | C7: 612 | D7: =IF(LEFT(B7,9)="Very high",100,IF(LEFT(B7,4)="High",80,IF(LEFT(B7,8)="Moderate",60,IF(LEFT(B7,3)="Low",40,IF(LEFT(B7,8)="Very low",20))))) -> 100 | G7: Portugal | H7: Very high proficiency | I7: 605
A8: Denmark | B8: Very high proficiency | C8: 611 | D8: =IF(LEFT(B8,9)="Very high",100,IF(LEFT(B8,4)="High",80,IF(LEFT(B8,8)="Moderate",60,IF(LEFT(B8,3)="Low",40,IF(LEFT(B8,8)="Very low",20))))) -> 100 | G8: Denmark | H8: Very high proficiency | I8: 603
A9: Sweden | B9: Very high proficiency | C9: 609 | D9: =IF(LEFT(B9,9)="Very high",100,IF(LEFT(B9,4)="High",80,IF(LEFT(B9,8)="Moderate",60,IF(LEFT(B9,3)="Low",40,IF(LEFT(B9,8)="Very low",20))))) -> 100 | G9: Greece | H9: Very high proficiency | I9: 602
A10: Belgium | B10: Very high proficiency | C10: 608 | D10: =IF(LEFT(B10,9)="Very high",100,IF(LEFT(B10,4)="High",80,IF(LEFT(B10,8)="Moderate",60,IF(LEFT(B10,3)="Low",40,IF(LEFT(B10,8)="Very low",20))))) -> 100 | G10: Austria | H10: Very high proficiency | I10: 600
A11: Slovakia | B11: Very high proficiency | C11: 606 | D11: =IF(LEFT(B11,9)="Very high",100,IF(LEFT(B11,4)="High",80,IF(LEFT(B11,8)="Moderate",60,IF(LEFT(B11,3)="Low",40,IF(LEFT(B11,8)="Very low",20))))) -> 100 | G11: Germany | H11: High Proficiency | I11: 598
A12: Romania | B12: Very high proficiency | C12: 605 | D12: =IF(LEFT(B12,9)="Very high",100,IF(LEFT(B12,4)="High",80,IF(LEFT(B12,8)="Moderate",60,IF(LEFT(B12,3)="Low",40,IF(LEFT(B12,8)="Very low",20))))) -> 100 | G12: South Africa | H12: High Proficiency | I12: 594
A13: Finland | B13: Very high proficiency | C13: 603 | D13: =IF(LEFT(B13,9)="Very high",100,IF(LEFT(B13,4)="High",80,IF(LEFT(B13,8)="Moderate",60,IF(LEFT(B13,3)="Low",40,IF(LEFT(B13,8)="Very low",20))))) -> 100 | G13: Romania | H13: High proficiency | I13: 593
... A117: Thailand | B117: Very low proficiency | C117: 402 | D117: =IF(LEFT(B117,9)="Very high",100,IF(LEFT(B117,4)="High",80,IF(LEFT(B117,8)="Moderate",60,IF(LEFT(B117,3)="Low",40,IF(LEFT(B117,8)="Very low",20))))) -> 20 | G117: Yemen | H117: Very low proficiency | I117: 394
A118: Yemen | B118: Very low proficiency | C118: 402 | D118: =IF(LEFT(B118,9)="Very high",100,IF(LEFT(B118,4)="High",80,IF(LEFT(B118,8)="Moderate",60,IF(LEFT(B118,3)="Low",40,IF(LEFT(B118,8)="Very low",20))))) -> 20
A119: Democratic Republic of the Congo | B119: Very low proficiency | C119: 400 | D119: =IF(LEFT(B119,9)="Very high",100,IF(LEFT(B119,4)="High",80,IF(LEFT(B119,8)="Moderate",60,IF(LEFT(B119,3)="Low",40,IF(LEFT(B119,8)="Very low",20))))) -> 20
A120: Somalia | B120: Very low proficiency | C120: 398 | D120: =IF(LEFT(B120,9)="Very high",100,IF(LEFT(B120,4)="High",80,IF(LEFT(B120,8)="Moderate",60,IF(LEFT(B120,3)="Low",40,IF(LEFT(B120,8)="Very low",20))))) -> 20
A121: Togo | B121: Very low proficiency | C121: 397 | D121: =IF(LEFT(B121,9)="Very high",100,IF(LEFT(B121,4)="High",80,IF(LEFT(B121,8)="Moderate",60,IF(LEFT(B121,3)="Low",40,IF(LEFT(B121,8)="Very low",20))))) -> 20
A122: Libya | B122: Very low proficiency | C122: 395 | D122: =IF(LEFT(B122,9)="Very high",100,IF(LEFT(B122,4)="High",80,IF(LEFT(B122,8)="Moderate",60,IF(LEFT(B122,3)="Low",40,IF(LEFT(B122,8)="Very low",20))))) -> 20
A123: Ivory Coast | B123: Very low proficiency | C123: 393 | D123: =IF(LEFT(B123,9)="Very high",100,IF(LEFT(B123,4)="High",80,IF(LEFT(B123,8)="Moderate",60,IF(LEFT(B123,3)="Low",40,IF(LEFT(B123,8)="Very low",20))))) -> 20
A124: Cambodia | B124: Very low proficiency | C124: 390 | D124: =IF(LEFT(B124,9)="Very high",100,IF(LEFT(B124,4)="High",80,IF(LEFT(B124,8)="Moderate",60,IF(LEFT(B124,3)="Low",40,IF(LEFT(B124,8)="Very low",20))))) -> 20
A125: Singapore | B125: Very high proficiency (2024, carried over: not in EF 2025) | C125: 609 | D125: =IF(LEFT(B125,9)="Very high",100,IF(LEFT(B125,4)="High",80,IF(LEFT(B125,8)="Moderate",60,IF(LEFT(B125,3)="Low",40,IF(LEFT(B125,8)="Very low",20))))) -> 100
A126: Luxembourg | B126: High proficiency (2024, carried over: not in EF 2025) | C126: 576 | D126: =IF(LEFT(B126,9)="Very high",100,IF(LEFT(B126,4)="High",80,IF(LEFT(B126,8)="Moderate",60,IF(LEFT(B126,3)="Low",40,IF(LEFT(B126,8)="Very low",20))))) -> 80

Sheet Openness
A1: Country | B1: Openness_2024 | C1: InterNations Expat Insider 2024, Ease of Settling In rank (1=best). Kept as active: 2026 edition ranks only 31 countries. | E1: Country | F1: Openness_2026 | G1: Expat Insider 2026 (31 countries) - stored for reference, not used.
A2: Costa Rica | B2: 1 | E2: Mexico | F2: 1
A3: Mexico | B3: 2 | E3: Panama | F3: 2
A4: Philippines | B4: 3 | E4: Thailand | F4: 3
A5: Indonesia | B5: 4 | E5: Brazil | F5: 4
A6: Brazil | B6: 5 | E6: United Arab Emirates | F6: 5
A7: Thailand | B7: 6 | E7: Spain | F7: 6
A8: Panama | B8: 7 | E8: Portugal | F8: 7
A9: Colombia | B9: 8 | E9: Ireland | F9: 8
A10: Kenya | B10: 9 | E10: United States | F10: 9
A11: Greece | B11: 10 | E11: South Africa | F11: 10
A12: Spain | B12: 11 | E12: Australia | F12: 11
A13: Oman | B13: 12 | E13: Singapore | F13: 12
... A32: Belgium | B32: 31 | E32: Norway | F32: 31
A33: Malta | B33: 32
A34: Italy | B34: 33
A35: France | B35: 34
A36: Japan | B36: 35
A37: South Korea | B37: 36
A38: Poland | B38: 37
A39: Luxembourg | B39: 38
A40: Canada | B40: 39
A41: Turkey | B41: 40
A42: Netherlands | B42: 41
A43: United Kingdom | B43: 42
A44: Chile | B44: 43
... A54: Kuwait | B54: 53

Sheet Scenic
A1: Country | B1: Rank | C1: source https://www.usnews.com/news/best-countries/rankings/scenic?utm_source=chatgpt.com
A2: Greece | B2: 1 | C2: 2024 data
A3: New Zealand | B3: 2
A4: Italy | B4: 3
A5: Switzerland | B5: 4
A6: Spain | B6: 5
A7: Thailand | B7: 6
A8: Norway | B8: 7
A9: Iceland | B9: 8
A10: Australia | B10: 9
A11: Austria | B11: 10
A12: Ireland | B12: 11
A13: Brazil | B13: 12
A14: Portugal | B14: 13
... A90: Iran | B90: 89

Sheet Disaster
A1: Country | B1: Rank | C1: W | D1: E | E1: V | F1: StormRiskIndex | G1: StormRiskRank | H1: Disaster_2026: WorldRiskReport 2026, p.58-61. W = WorldRiskIndex (used by tab 1, col C). E = Exposure, V = Vulnerability. | J1: WRI.Country | K1: ISO3.Code | L1: W | M1: E | N1: V | O1: S | P1: C | Q1: A | R1: Disaster_2024 (old). Korea rows corrected (PRK was labelled South Korea).
A2: Philippines | B2: 1 | C2: 46.69 | D2: 40.76 | E2: 53.49 | F2: 69.27 | G2: 1 | J2: Philippines | K2: PHL | L2: 46.91 | M2: 39.99 | N2: 55.03 | O2: 51.16 | P2: 58.07 | Q2: 56.1
A3: India | B3: 2 | C3: 44.97 | D3: 40.83 | E3: 49.54 | F3: 11.99 | G3: 14 | J3: Indonesia | K3: IDN | L3: 41.13 | M3: 39.89 | N3: 42.4 | O3: 32.37 | P3: 51.01 | Q3: 46.17
A4: Indonesia | B4: 3 | C4: 44.63 | D4: 39.78 | E4: 50.08 | F4: 11.69 | G4: 15 | J4: India | K4: IND | L4: 40.96 | M4: 35.99 | N4: 46.62 | O4: 37.15 | P4: 54.01 | Q4: 50.49
A5: Colombia | B5: 4 | C5: 39.8 | D5: 31.59 | E5: 50.14 | F5: 10.88 | G5: 17 | J5: Colombia | K5: COL | L5: 37.81 | M5: 31.54 | N5: 45.33 | O5: 39.3 | P5: 49.28 | Q5: 48.1
A6: Mexico | B6: 5 | C6: 39.18 | D6: 50.69 | E6: 30.28 | F6: 47.4 | G6: 2 | J6: Mexico | K6: MEX | L6: 35.93 | M6: 50.08 | N6: 25.78 | O6: 30.03 | P6: 11.97 | Q6: 47.68
A7: Myanmar | B7: 6 | C7: 37.51 | D7: 22.44 | E7: 62.7 | F7: 13.39 | G7: 13 | J7: Myanmar | K7: MMR | L7: 35.85 | M7: 22.43 | N7: 57.31 | O7: 51.43 | P7: 58.75 | Q7: 62.29
A8: Mozambique | B8: 7 | C8: 30.92 | D8: 14.69 | E8: 65.09 | F8: 13.72 | G8: 12 | J8: Mozambique | K8: MOZ | L8: 34.44 | M8: 18.1 | N8: 65.53 | O8: 65.79 | P8: 63.13 | Q8: 67.75
A9: Russia | B9: 8 | C9: 30.58 | D9: 28.37 | E9: 32.97 | F9: 8.86 | G9: 23 | J9: Russia | K9: RUS | L9: 28.12 | M9: 28.35 | N9: 27.89 | O9: 15.31 | P9: 40.03 | Q9: 35.38
A10: China | B10: 9 | C10: 29.54 | D10: 71.06 | E10: 12.28 | F10: 30.38 | G10: 6 | J10: Bangladesh | K10: BGD | L10: 27.73 | M10: 16.57 | N10: 46.39 | O10: 35.5 | P10: 57.92 | Q10: 48.54
A11: Somalia | B11: 10 | C11: 29.12 | D11: 11.94 | E11: 71 | F11: 0.84 | G11: 71 | J11: Pakistan | K11: PAK | L11: 27.02 | M11: 13.11 | N11: 55.69 | O11: 42.64 | P11: 63.1 | Q11: 64.18
A12: Honduras | B12: 11 | C12: 27.68 | D12: 21.89 | E12: 34.99 | F12: 10.04 | G12: 18 | J12: Peru | K12: PER | L12: 27.01 | M12: 16.65 | N12: 43.82 | O12: 36.32 | P12: 46.06 | Q12: 50.3
A13: Papua New Guinea | B13: 12 | C13: 27.64 | D13: 21.2 | E13: 36.04 | F13: 2.33 | G13: 53 | J13: Papua New Guinea | K13: PNG | L13: 26.35 | M13: 18.84 | N13: 36.84 | O13: 57.46 | P13: 13.59 | Q13: 64.04
... A194: Monaco | B194: 193 | C194: 0.21 | D194: 0.02 | E194: 2.28 | F194: 0.15 | G194: 193 | J194: Monaco | K194: MCO | L194: 0.18 | M194: 0.02 | N194: 1.57 | O194: 1.68 | P194: 0.44 | Q194: 5.25

Sheet LifeExp60
A1: Country | B1: LifeExp60_2024 | C1: Female | D1: Male | E1: Life expectancy at age 60 (remaining years), 2024. Source: UN World Population Prospects, via World Bank Gender Data Portal (SP.DYN.LE60.FE.IN / .MA.IN). Col B = average of female and male; MALE COLUMN EMPTY for now (first export was scrambled) -> B currently = female only. Paste correct male values in col D and B updates automatically.
A2: Monaco | B2: =AVERAGE(C2:D2) -> 29.859 | C2: 29.859
A3: Hong Kong (China) | B3: =AVERAGE(C3:D3) -> 29.811 | C3: 29.811
A4: Japan | B4: =AVERAGE(C4:D4) -> 29.482 | C4: 29.482
A5: Gibraltar | B5: =AVERAGE(C5:D5) -> 28.572 | C5: 28.572
A6: San Marino | B6: =AVERAGE(C6:D6) -> 28.519 | C6: 28.519
A7: South Korea | B7: =AVERAGE(C7:D7) -> 28.35 | C7: 28.35
A8: France | B8: =AVERAGE(C8:D8) -> 28.253 | C8: 28.253
A9: French Polynesia | B9: =AVERAGE(C9:D9) -> 28.201 | C9: 28.201
A10: Spain | B10: =AVERAGE(C10:D10) -> 27.982 | C10: 27.982
A11: Andorra | B11: =AVERAGE(C11:D11) -> 27.89 | C11: 27.89
A12: Bermuda | B12: =AVERAGE(C12:D12) -> 27.86 | C12: 27.86
A13: Singapore | B13: =AVERAGE(C13:D13) -> 27.825 | C13: 27.825
... A217: Nigeria | B217: =AVERAGE(C217:D217) -> 15.473 | C217: 15.473

Sheet CGT
A1: Country | B1: CGT | C1: Providing headline number | D1: https://taxsummaries.pwc.com/quick-charts/capital-gains-tax-cgt-rates
A2: Switzerland | B2: 0
A3: Luxembourg
A4: United States
A5: Singapore
A6: Iceland
A7: Denmark
A8: Australia
A9: Hong Kong (China)
A10: Netherlands
A11: Norway
A12: United Kingdom
A13: United Arab Emirates
A14: New Zealand
... A107: Nigeria

Sheet Sheet1
A1: Country | B1: Col_2026MY | C1: Sal_2026 | E1: Country | F1: Col_2025 | G1: Numbeo Cost of Living Plus Rent Index. Active: 2026 Mid-Year (A:B). Older year kept for comparison.
A2: Bermuda | B2: 122.1 | C2: =VLOOKUP(A2, Salary!A:B, 2, FALSE()) -> #N/A | E2: Us Virgin Islands | F2: 75.4
A3: Cayman Islands | B3: 99 | C3: =VLOOKUP(A3, Salary!A:B, 2, FALSE()) -> #N/A | E3: Switzerland | F3: 74.8
A4: Switzerland | B4: 81.5 | C4: =VLOOKUP(A4, Salary!A:B, 2, FALSE()) -> 7112.01 | E4: Singapore | F4: 73.7
A5: Singapore | B5: 80.5 | C5: =VLOOKUP(A5, Salary!A:B, 2, FALSE()) -> 4469.53 | E5: Bahamas | F5: 66.1
A6: Bahamas | B6: 77.2 | C6: =VLOOKUP(A6, Salary!A:B, 2, FALSE()) -> #N/A | E6: Iceland | F6: 65.9
A7: Iceland | B7: 74.8 | C7: =VLOOKUP(A7, Salary!A:B, 2, FALSE()) -> 4742.72 | E7: Hong Kong (China) | F7: 65.7
A8: Jersey | B8: 71.6 | C8: =VLOOKUP(A8, Salary!A:B, 2, FALSE()) -> #N/A | E8: Guernsey | F8: 57.1
A9: Hong Kong (China) | B9: 68.5 | C9: =VLOOKUP(A9, Salary!A:B, 2, FALSE()) -> 3266.5 | E9: Luxembourg | F9: 54.8
A10: Turkmenistan | B10: 66.1 | C10: =VLOOKUP(A10, Salary!A:B, 2, FALSE()) -> #N/A | E10: United States | F10: 54.3
A11: Solomon Islands | B11: 65.7 | C11: =VLOOKUP(A11, Salary!A:B, 2, FALSE()) -> #N/A | E11: Papua New Guinea | F11: 53.7
A12: Israel | B12: 64.8 | C12: =VLOOKUP(A12, Salary!A:B, 2, FALSE()) -> 3678.8 | E12: Ireland | F12: 50.6
A13: Guernsey | B13: 64.5 | C13: =VLOOKUP(A13, Salary!A:B, 2, FALSE()) -> #N/A | E13: Norway | F13: 49.4
... A140: Tanzania | B140: 17.5 | C140: =VLOOKUP(A140, Salary!A:B, 2, FALSE()) -> #N/A | E140: Pakistan | F140: 11.2
A141: Syria | B141: 17.3 | C141: =VLOOKUP(A141, Salary!A:B, 2, FALSE()) -> #N/A
A142: Indonesia | B142: 17 | C142: =VLOOKUP(A142, Salary!A:B, 2, FALSE()) -> 260.19
A143: Nigeria | B143: 16.6 | C143: =VLOOKUP(A143, Salary!A:B, 2, FALSE()) -> #N/A
A144: Madagascar | B144: 16.5 | C144: =VLOOKUP(A144, Salary!A:B, 2, FALSE()) -> #N/A
A145: Algeria | B145: 16.1 | C145: =VLOOKUP(A145, Salary!A:B, 2, FALSE()) -> 295.6
A146: Iran | B146: 15.1 | C146: =VLOOKUP(A146, Salary!A:B, 2, FALSE()) -> 246.03
A147: Bangladesh | B147: 13.4 | C147: =VLOOKUP(A147, Salary!A:B, 2, FALSE()) -> 224.13
A148: Egypt | B148: 13.4 | C148: =VLOOKUP(A148, Salary!A:B, 2, FALSE()) -> 138.65
A149: Nepal | B149: 13.2 | C149: =VLOOKUP(A149, Salary!A:B, 2, FALSE()) -> 211.67
A150: Afghanistan | B150: 12.9 | C150: =VLOOKUP(A150, Salary!A:B, 2, FALSE()) -> #N/A
A151: Libya | B151: 12.7 | C151: =VLOOKUP(A151, Salary!A:B, 2, FALSE()) -> #N/A
A152: Pakistan | B152: 12.4 | C152: =VLOOKUP(A152, Salary!A:B, 2, FALSE()) -> 191.7
